Workbook

Sheet yoll_Europe
A2: Premature mortality due to PM2.5
A3: Scenario: A1/d/D/v5a
A4: Region:
A5: Year: 2040
A6: Unit: -,mln people, μg/m3, mln years,cases,cases
A7: UserID: StefanA
C9: Total Population (2010) | D9: Mean PM<sub>2.5</sub><br>concentration | E9: YOLL | F9: Months lost | G9: Premature deaths static | H9: Premature deaths
A10: EU27 | B10: Austria | C10: 8.41 | D10: 3.557 | E10: 36798 | F10: 2.446 | G10: 2046 | H10: 2649
A11: EU27 | B11: Belgium | C11: 10.939 | D11: 4.606 | E11: 61903 | F11: 3.257 | G11: 3636 | H11: 4337
A12: EU27 | B12: Bulgaria | C12: 7.405 | D12: 4.182 | E12: 39012 | F12: 3.376 | G12: 3487 | H12: 3176
A13: EU27 | B13: Croatia | C13: 4.328 | D13: 4.132 | E13: 21547 | F13: 3.336 | G13: 1596 | H13: 1644
A14: EU27 | B14: Cyprus | C14: 1.113 | D14: 5.407 | E14: 6482 | F14: 3.95 | G14: 293 | H14: 471
A15: EU27 | B15: Czech Republic | C15: 10.536 | D15: 4.017 | E15: 53576 | F15: 3.124 | G15: 3214 | H15: 4032
A16: EU27 | B16: Denmark | C16: 5.555 | D16: 3.081 | E16: 21527 | F16: 2.283 | G16: 1280 | H16: 1565
A17: EU27 | B17: Estonia | C17: 1.332 | D17: 2.681 | E17: 4510 | F17: 2.198 | G17: 341 | H17: 321
A18: EU27 | B18: Finland | C18: 5.366 | D18: 2.194 | E18: 15100 | F18: 1.551 | G18: 815 | H18: 1112
A19: EU27 | B19: France | C19: 63.027 | D19: 3.88 | E19: 312565 | F19: 2.753 | G19: 15493 | H19: 20631
A20: EU27 | B20: Germany | C20: 80.895 | D20: 3.775 | E20: 388205 | F20: 2.67 | G20: 23905 | H20: 28410
A21: EU27 | B21: Greece | C21: 11.446 | D21: 5.492 | E21: 71531 | F21: 3.945 | G21: 4358 | H21: 5274
... A36: EU27 | B36: Sweden | C36: 9.39 | D36: 2.381 | E36: 26690 | F36: 1.557 | G36: 1638 | H36: 1963
A37: EU27 Total | C37: 440.529 | D37: 4.295 | E37: 2359307 | F37: 3.117 | G37: 138847 | H37: 169118
A38: NON EU27 | B38: Albania | C38: 2.941 | D38: 6.723 | E38: 20196 | F38: 5.113 | G38: 964 | H38: 1526
A39: NON EU27 | B39: Armenia | C39: 2.877 | D39: 7.457 | E39: 25787 | F39: 6.74 | G39: 1517 | H39: 1791
A40: NON EU27 | B40: Azerbaijan | C40: 9.032 | D40: 5.664 | E40: 63495 | F40: 5.039 | G40: 2122 | H40: 4448
A41: NON EU27 | B41: Belarus | C41: 9.473 | D41: 5.414 | E41: 72414 | F41: 4.984 | G41: 5794 | H41: 5067
A42: NON EU27 | B42: Bosnia and Herzegovina | C42: 3.722 | D42: 7.44 | E42: 32668 | F42: 6.18 | G42: 1941 | H42: 2438
A43: NON EU27 | B43: Georgia | C43: 4.232 | D43: 6.67 | E43: 30920 | F43: 5.601 | G43: 2450 | H43: 2395
A44: NON EU27 | B44: Iceland | C44: 0.32 | D44: 2.658 | E44: 888 | F44: 1.783 | G44: 39 | H44: 63
A45: NON EU27 | B45: Kazakhstan | C45: 16.399 | D45: 12.813 | E45: 273011 | F45: 11.912 | G45: 14273 | H45: 18644
A46: NON EU27 | B46: Kosovo | C46: 1.827 | D46: 11.661 | E46: 9051 | F46: 9.213 | G46: 717 | H46: 731
A47: NON EU27 | B47: Kyrgyzstan | C47: 5.422 | D47: 8.691 | E47: 51698 | F47: 7.827 | G47: 2228 | H47: 3364
A48: NON EU27 | B48: North Macedonia | C48: 2.071 | D48: 6.974 | E48: 16134 | F48: 5.51 | G48: 994 | H48: 1302
A49: NON EU27 | B49: Republic of Moldova | C49: 4.084 | D49: 5.902 | E49: 31569 | F49: 5.278 | G49: 2160 | H49: 2366
... A60: NON EU27 | B60: Uzbekistan | C60: 28.606 | D60: 8.386 | E60: 283778 | F60: 7.905 | G60: 8346 | H60: 17877
A61: NON EU27 Total | C61: 411.759 | D61: 6.541 | E61: 3316824 | F61: 5.667 | G61: 191162 | H61: 229551

Sheet yoll_Europe (1)
A2: Premature mortality due to PM2.5
A3: Scenario: A1/d/G/v5a
A4: Region:
A5: Year: 2040
A6: Unit: -,mln people, μg/m3, mln years,cases,cases
A7: UserID: StefanA
C9: Total Population (2010) | D9: Mean PM<sub>2.5</sub><br>concentration | E9: YOLL | F9: Months lost | G9: Premature deaths static | H9: Premature deaths
A10: EU27 | B10: Austria | C10: 8.41 | D10: 3.899 | E10: 40337 | F10: 2.682 | G10: 2242 | H10: 2904
A11: EU27 | B11: Belgium | C11: 10.939 | D11: 5.089 | E11: 68385 | F11: 3.598 | G11: 4017 | H11: 4791
A12: EU27 | B12: Bulgaria | C12: 7.405 | D12: 4.989 | E12: 46542 | F12: 4.027 | G12: 4161 | H12: 3789
A13: EU27 | B13: Croatia | C13: 4.328 | D13: 4.91 | E13: 25603 | F13: 3.964 | G13: 1897 | H13: 1953
A14: EU27 | B14: Cyprus | C14: 1.113 | D14: 6.2 | E14: 7434 | F14: 4.529 | G14: 336 | H14: 540
A15: EU27 | B15: Czech Republic | C15: 10.536 | D15: 4.577 | E15: 61043 | F15: 3.559 | G15: 3662 | H15: 4594
A16: EU27 | B16: Denmark | C16: 5.555 | D16: 3.34 | E16: 23341 | F16: 2.475 | G16: 1388 | H16: 1697
A17: EU27 | B17: Estonia | C17: 1.332 | D17: 2.918 | E17: 4908 | F17: 2.392 | G17: 371 | H17: 349
A18: EU27 | B18: Finland | C18: 5.366 | D18: 2.377 | E18: 16357 | F18: 1.68 | G18: 883 | H18: 1205
A19: EU27 | B19: France | C19: 63.027 | D19: 4.303 | E19: 346634 | F19: 3.053 | G19: 17182 | H19: 22879
A20: EU27 | B20: Germany | C20: 80.895 | D20: 4.111 | E20: 422782 | F20: 2.907 | G20: 26034 | H20: 30940
A21: EU27 | B21: Greece | C21: 11.446 | D21: 6.149 | E21: 80091 | F21: 4.417 | G21: 4880 | H21: 5905
... A36: EU27 | B36: Sweden | C36: 9.39 | D36: 2.531 | E36: 28365 | F36: 1.655 | G36: 1740 | H36: 2086
A37: EU27 Total | C37: 440.529 | D37: 4.716 | E37: 2592607 | F37: 3.434 | G37: 152983 | H37: 185912
A38: NON EU27 | B38: Albania | C38: 2.941 | D38: 9.728 | E38: 29222 | F38: 7.399 | G38: 1395 | H38: 2208
A39: NON EU27 | B39: Armenia | C39: 2.877 | D39: 9.48 | E39: 32782 | F39: 8.568 | G39: 1928 | H39: 2277
A40: NON EU27 | B40: Azerbaijan | C40: 9.032 | D40: 6.39 | E40: 71633 | F40: 5.685 | G40: 2394 | H40: 5019
A41: NON EU27 | B41: Belarus | C41: 9.473 | D41: 6.394 | E41: 85528 | F41: 5.887 | G41: 6843 | H41: 5985
A42: NON EU27 | B42: Bosnia and Herzegovina | C42: 3.722 | D42: 11.846 | E42: 52018 | F42: 9.84 | G42: 3091 | H42: 3883
A43: NON EU27 | B43: Georgia | C43: 4.232 | D43: 8.426 | E43: 39056 | F43: 7.075 | G43: 3094 | H43: 3025
A44: NON EU27 | B44: Iceland | C44: 0.32 | D44: 3.021 | E44: 1010 | F44: 2.027 | G44: 44 | H44: 71
A45: NON EU27 | B45: Kazakhstan | C45: 16.399 | D45: 15.572 | E45: 331807 | F45: 14.478 | G45: 17347 | H45: 22660
A46: NON EU27 | B46: Kosovo | C46: 1.827 | D46: 19.753 | E46: 15332 | F46: 15.606 | G46: 1214 | H46: 1237
A47: NON EU27 | B47: Kyrgyzstan | C47: 5.422 | D47: 10.951 | E47: 65144 | F47: 9.863 | G47: 2807 | H47: 4240
A48: NON EU27 | B48: North Macedonia | C48: 2.071 | D48: 10.513 | E48: 24322 | F48: 8.306 | G48: 1498 | H48: 1963
A49: NON EU27 | B49: Republic of Moldova | C49: 4.084 | D49: 8.653 | E49: 46280 | F49: 7.738 | G49: 3167 | H49: 3469
... A60: NON EU27 | B60: Uzbekistan | C60: 28.606 | D60: 10.025 | E60: 339230 | F60: 9.45 | G60: 9977 | H60: 21371
A61: NON EU27 Total | C61: 411.759 | D61: 8.178 | E61: 4152002 | F61: 7.108 | G61: 242731 | H61: 288079

Sheet yoll_Europe (2)
A2: Premature mortality due to PM2.5
A3: Scenario: A1/s/D/v5a
A4: Region:
A5: Year: 2040
A6: Unit: -,mln people, μg/m3, mln years,cases,cases
A7: UserID: StefanA
C9: Total Population (2010) | D9: Mean PM<sub>2.5</sub><br>concentration | E9: YOLL | F9: Months lost | G9: Premature deaths static | H9: Premature deaths
A10: EU27 | B10: Austria | C10: 8.41 | D10: 3.449 | E10: 35676 | F10: 2.372 | G10: 1983 | H10: 2568
A11: EU27 | B11: Belgium | C11: 10.939 | D11: 4.509 | E11: 60600 | F11: 3.188 | G11: 3560 | H11: 4246
A12: EU27 | B12: Bulgaria | C12: 7.405 | D12: 4.082 | E12: 38083 | F12: 3.295 | G12: 3404 | H12: 3100
A13: EU27 | B13: Croatia | C13: 4.328 | D13: 4.016 | E13: 20941 | F13: 3.243 | G13: 1551 | H13: 1598
A14: EU27 | B14: Cyprus | C14: 1.113 | D14: 5.441 | E14: 6523 | F14: 3.975 | G14: 295 | H14: 474
A15: EU27 | B15: Czech Republic | C15: 10.536 | D15: 3.918 | E15: 52256 | F15: 3.047 | G15: 3135 | H15: 3933
A16: EU27 | B16: Denmark | C16: 5.555 | D16: 2.926 | E16: 20448 | F16: 2.168 | G16: 1216 | H16: 1486
A17: EU27 | B17: Estonia | C17: 1.332 | D17: 2.508 | E17: 4219 | F17: 2.056 | G17: 319 | H17: 300
A18: EU27 | B18: Finland | C18: 5.366 | D18: 2.089 | E18: 14376 | F18: 1.476 | G18: 776 | H18: 1059
A19: EU27 | B19: France | C19: 63.027 | D19: 3.874 | E19: 312083 | F19: 2.748 | G19: 15470 | H19: 20599
A20: EU27 | B20: Germany | C20: 80.895 | D20: 3.699 | E20: 380453 | F20: 2.616 | G20: 23428 | H20: 27842
A21: EU27 | B21: Greece | C21: 11.446 | D21: 5.485 | E21: 71446 | F21: 3.94 | G21: 4353 | H21: 5268
... A36: EU27 | B36: Sweden | C36: 9.39 | D36: 2.321 | E36: 26016 | F36: 1.518 | G36: 1596 | H36: 1913
A37: EU27 Total | C37: 440.529 | D37: 4.195 | E37: 2304327 | F37: 3.042 | G37: 135576 | H37: 165176
A38: NON EU27 | B38: Albania | C38: 2.941 | D38: 7.082 | E38: 21273 | F38: 5.386 | G38: 1015 | H38: 1607
A39: NON EU27 | B39: Armenia | C39: 2.877 | D39: 7.635 | E39: 26403 | F39: 6.901 | G39: 1553 | H39: 1834
A40: NON EU27 | B40: Azerbaijan | C40: 9.032 | D40: 5.621 | E40: 63013 | F40: 5.001 | G40: 2106 | H40: 4415
A41: NON EU27 | B41: Belarus | C41: 9.473 | D41: 4.926 | E41: 65890 | F41: 4.535 | G41: 5272 | H41: 4611
A42: NON EU27 | B42: Bosnia and Herzegovina | C42: 3.722 | D42: 7.737 | E42: 33975 | F42: 6.427 | G42: 2019 | H42: 2536
A43: NON EU27 | B43: Georgia | C43: 4.232 | D43: 6.416 | E43: 29742 | F43: 5.388 | G43: 2356 | H43: 2304
A44: NON EU27 | B44: Iceland | C44: 0.32 | D44: 2.696 | E44: 901 | F44: 1.809 | G44: 39 | H44: 64
A45: NON EU27 | B45: Kazakhstan | C45: 16.399 | D45: 12.822 | E45: 273211 | F45: 11.921 | G45: 14284 | H45: 18658
A46: NON EU27 | B46: Kosovo | C46: 1.827 | D46: 11.682 | E46: 9067 | F46: 9.229 | G46: 718 | H46: 732
A47: NON EU27 | B47: Kyrgyzstan | C47: 5.422 | D47: 8.462 | E47: 50339 | F47: 7.621 | G47: 2169 | H47: 3276
A48: NON EU27 | B48: North Macedonia | C48: 2.071 | D48: 7.129 | E48: 16494 | F48: 5.632 | G48: 1016 | H48: 1331
A49: NON EU27 | B49: Republic of Moldova | C49: 4.084 | D49: 6.022 | E49: 32207 | F49: 5.385 | G49: 2204 | H49: 2414
... A60: NON EU27 | B60: Uzbekistan | C60: 28.606 | D60: 8.649 | E60: 292674 | F60: 8.153 | G60: 8608 | H60: 18438
A61: NON EU27 Total | C61: 411.759 | D61: 6.668 | E61: 3381716 | F61: 5.78 | G61: 195442 | H61: 234126

Sheet yoll_Europe (3)
A2: Premature mortality due to PM2.5
A3: Scenario: A1/s/G/v5a
A4: Region:
A5: Year: 2040
A6: Unit: -,mln people, μg/m3, mln years,cases,cases
A7: UserID: StefanA
C9: Total Population (2010) | D9: Mean PM<sub>2.5</sub><br>concentration | E9: YOLL | F9: Months lost | G9: Premature deaths static | H9: Premature deaths
A10: EU27 | B10: Austria | C10: 8.41 | D10: 3.84 | E10: 39730 | F10: 2.641 | G10: 2209 | H10: 2860
A11: EU27 | B11: Belgium | C11: 10.939 | D11: 5.004 | E11: 67250 | F11: 3.538 | G11: 3950 | H11: 4712
A12: EU27 | B12: Bulgaria | C12: 7.405 | D12: 4.977 | E12: 46434 | F12: 4.018 | G12: 4151 | H12: 3780
A13: EU27 | B13: Croatia | C13: 4.328 | D13: 4.717 | E13: 24594 | F13: 3.808 | G13: 1822 | H13: 1876
A14: EU27 | B14: Cyprus | C14: 1.113 | D14: 6.114 | E14: 7331 | F14: 4.467 | G14: 331 | H14: 533
A15: EU27 | B15: Czech Republic | C15: 10.536 | D15: 4.508 | E15: 60122 | F15: 3.506 | G15: 3607 | H15: 4525
A16: EU27 | B16: Denmark | C16: 5.555 | D16: 3.25 | E16: 22713 | F16: 2.408 | G16: 1351 | H16: 1651
A17: EU27 | B17: Estonia | C17: 1.332 | D17: 2.831 | E17: 4762 | F17: 2.32 | G17: 360 | H17: 338
A18: EU27 | B18: Finland | C18: 5.366 | D18: 2.31 | E18: 15895 | F18: 1.632 | G18: 858 | H18: 1171
A19: EU27 | B19: France | C19: 63.027 | D19: 4.218 | E19: 339820 | F19: 2.993 | G19: 16844 | H19: 22430
A20: EU27 | B20: Germany | C20: 80.895 | D20: 4.079 | E20: 419452 | F20: 2.884 | G20: 25829 | H20: 30696
A21: EU27 | B21: Greece | C21: 11.446 | D21: 6.089 | E21: 79305 | F21: 4.374 | G21: 4832 | H21: 5847
... A36: EU27 | B36: Sweden | C36: 9.39 | D36: 2.484 | E36: 27840 | F36: 1.624 | G36: 1708 | H36: 2047
A37: EU27 Total | C37: 440.529 | D37: 4.65 | E37: 2555449 | F37: 3.383 | G37: 150855 | H37: 183290
A38: NON EU27 | B38: Albania | C38: 2.941 | D38: 9.087 | E38: 27296 | F38: 6.911 | G38: 1303 | H38: 2062
A39: NON EU27 | B39: Armenia | C39: 2.877 | D39: 10.989 | E39: 38003 | F39: 9.933 | G39: 2235 | H39: 2639
A40: NON EU27 | B40: Azerbaijan | C40: 9.032 | D40: 7.382 | E40: 82754 | F40: 6.568 | G40: 2766 | H40: 5798
A41: NON EU27 | B41: Belarus | C41: 9.473 | D41: 6.249 | E41: 83584 | F41: 5.753 | G41: 6687 | H41: 5849
A42: NON EU27 | B42: Bosnia and Herzegovina | C42: 3.722 | D42: 10.429 | E42: 45795 | F42: 8.663 | G42: 2721 | H42: 3418
A43: NON EU27 | B43: Georgia | C43: 4.232 | D43: 8.21 | E43: 38058 | F43: 6.894 | G43: 3015 | H43: 2948
A44: NON EU27 | B44: Iceland | C44: 0.32 | D44: 2.956 | E44: 988 | F44: 1.983 | G44: 43 | H44: 70
A45: NON EU27 | B45: Kazakhstan | C45: 16.399 | D45: 16.205 | E45: 345286 | F45: 15.066 | G45: 18052 | H45: 23580
A46: NON EU27 | B46: Kosovo | C46: 1.827 | D46: 16.732 | E46: 12987 | F46: 13.219 | G46: 1028 | H46: 1048
A47: NON EU27 | B47: Kyrgyzstan | C47: 5.422 | D47: 10.595 | E47: 63027 | F47: 9.542 | G47: 2716 | H47: 4102
A48: NON EU27 | B48: North Macedonia | C48: 2.071 | D48: 9.432 | E48: 21822 | F48: 7.452 | G48: 1344 | H48: 1761
A49: NON EU27 | B49: Republic of Moldova | C49: 4.084 | D49: 8.062 | E49: 43121 | F49: 7.21 | G49: 2951 | H49: 3232
... A60: NON EU27 | B60: Uzbekistan | C60: 28.606 | D60: 10.114 | E60: 342230 | F60: 9.533 | G60: 10065 | H60: 21560
A61: NON EU27 Total | C61: 411.759 | D61: 8.204 | E61: 4171162 | F61: 7.134 | G61: 243251 | H61: 289203

Sheet yoll_Europe (4)
A2: Premature mortality due to PM2.5
A3: Scenario: A1r/d/D/v5a
A4: Region:
A5: Year: 2040
A6: Unit: -,mln people, μg/m3, mln years,cases,cases
A7: UserID: StefanA
C9: Total Population (2010) | D9: Mean PM<sub>2.5</sub><br>concentration | E9: YOLL | F9: Months lost | G9: Premature deaths static | H9: Premature deaths
A10: EU27 | B10: Austria | C10: 8.41 | D10: 3.521 | E10: 36422 | F10: 2.421 | G10: 2025 | H10: 2622
A11: EU27 | B11: Belgium | C11: 10.939 | D11: 4.451 | E11: 59811 | F11: 3.147 | G11: 3513 | H11: 4190
A12: EU27 | B12: Bulgaria | C12: 7.405 | D12: 4.015 | E12: 37453 | F12: 3.241 | G12: 3348 | H12: 3049
A13: EU27 | B13: Croatia | C13: 4.328 | D13: 4.167 | E13: 21728 | F13: 3.364 | G13: 1610 | H13: 1658
A14: EU27 | B14: Cyprus | C14: 1.113 | D14: 5.253 | E14: 6298 | F14: 3.837 | G14: 285 | H14: 458
A15: EU27 | B15: Czech Republic | C15: 10.536 | D15: 4.238 | E15: 56529 | F15: 3.296 | G15: 3392 | H15: 4254
A16: EU27 | B16: Denmark | C16: 5.555 | D16: 2.978 | E16: 20810 | F16: 2.207 | G16: 1238 | H16: 1513
A17: EU27 | B17: Estonia | C17: 1.332 | D17: 2.637 | E17: 4435 | F17: 2.161 | G17: 335 | H17: 315
A18: EU27 | B18: Finland | C18: 5.366 | D18: 2.167 | E18: 14908 | F18: 1.531 | G18: 804 | H18: 1098
A19: EU27 | B19: France | C19: 63.027 | D19: 3.842 | E19: 309513 | F19: 2.726 | G19: 15342 | H19: 20429
A20: EU27 | B20: Germany | C20: 80.895 | D20: 3.708 | E20: 381349 | F20: 2.622 | G20: 23483 | H20: 27908
A21: EU27 | B21: Greece | C21: 11.446 | D21: 5.464 | E21: 71170 | F21: 3.925 | G21: 4336 | H21: 5248
... A36: EU27 | B36: Sweden | C36: 9.39 | D36: 2.346 | E36: 26289 | F36: 1.534 | G36: 1613 | H36: 1933
A37: EU27 Total | C37: 440.529 | D37: 4.276 | E37: 2349285 | F37: 3.108 | G37: 138512 | H37: 168457
A38: NON EU27 | B38: Albania | C38: 2.941 | D38: 7.315 | E38: 21974 | F38: 5.564 | G38: 1049 | H38: 1660
A39: NON EU27 | B39: Armenia | C39: 2.877 | D39: 6.369 | E39: 22026 | F39: 5.757 | G39: 1295 | H39: 1530
A40: NON EU27 | B40: Azerbaijan | C40: 9.032 | D40: 5.443 | E40: 61022 | F40: 4.843 | G40: 2039 | H40: 4275
A41: NON EU27 | B41: Belarus | C41: 9.473 | D41: 5.146 | E41: 68836 | F41: 4.738 | G41: 5507 | H41: 4817
A42: NON EU27 | B42: Bosnia and Herzegovina | C42: 3.722 | D42: 9.493 | E42: 41684 | F42: 7.885 | G42: 2477 | H42: 3111
A43: NON EU27 | B43: Georgia | C43: 4.232 | D43: 7.491 | E43: 34722 | F43: 6.29 | G43: 2751 | H43: 2689
A44: NON EU27 | B44: Iceland | C44: 0.32 | D44: 2.614 | E44: 874 | F44: 1.753 | G44: 38 | H44: 62
A45: NON EU27 | B45: Kazakhstan | C45: 16.399 | D45: 13.937 | E45: 296965 | F45: 12.958 | G45: 15526 | H45: 20280
A46: NON EU27 | B46: Kosovo | C46: 1.827 | D46: 17.17 | E46: 13327 | F46: 13.565 | G46: 1055 | H46: 1076
A47: NON EU27 | B47: Kyrgyzstan | C47: 5.422 | D47: 6.334 | E47: 37681 | F47: 5.705 | G47: 1624 | H47: 2452
A48: NON EU27 | B48: North Macedonia | C48: 2.071 | D48: 9.529 | E48: 22046 | F48: 7.528 | G48: 1358 | H48: 1779
A49: NON EU27 | B49: Republic of Moldova | C49: 4.084 | D49: 7.294 | E49: 39011 | F49: 6.522 | G49: 2670 | H49: 2924
... A60: NON EU27 | B60: Uzbekistan | C60: 28.606 | D60: 7.862 | E60: 266040 | F60: 7.411 | G60: 7824 | H60: 16760
A61: NON EU27 Total | C61: 411.759 | D61: 6.373 | E61: 3236507 | F61: 5.521 | G61: 189414 | H61: 224843

Sheet yoll_Europe (5)
A2: Premature mortality due to PM2.5
A3: Scenario: A1r/d/G/v5a
A4: Region:
A5: Year: 2040
A6: Unit: -,mln people, μg/m3, mln years,cases,cases
A7: UserID: StefanA
C9: Total Population (2010) | D9: Mean PM<sub>2.5</sub><br>concentration | E9: YOLL | F9: Months lost | G9: Premature deaths static | H9: Premature deaths
A10: EU27 | B10: Austria | C10: 8.41 | D10: 3.449 | E10: 35676 | F10: 2.372 | G10: 1983 | H10: 2568
A11: EU27 | B11: Belgium | C11: 10.939 | D11: 4.47 | E11: 60076 | F11: 3.161 | G11: 3529 | H11: 4209
A12: EU27 | B12: Bulgaria | C12: 7.405 | D12: 4.034 | E12: 37637 | F12: 3.257 | G12: 3365 | H12: 3064
A13: EU27 | B13: Croatia | C13: 4.328 | D13: 4.034 | E13: 21037 | F13: 3.257 | G13: 1558 | H13: 1605
A14: EU27 | B14: Cyprus | C14: 1.113 | D14: 5.369 | E14: 6437 | F14: 3.922 | G14: 291 | H14: 468
A15: EU27 | B15: Czech Republic | C15: 10.536 | D15: 4.115 | E15: 54879 | F15: 3.2 | G15: 3293 | H15: 4130
A16: EU27 | B16: Denmark | C16: 5.555 | D16: 2.902 | E16: 20282 | F16: 2.151 | G16: 1206 | H16: 1474
A17: EU27 | B17: Estonia | C17: 1.332 | D17: 2.488 | E17: 4185 | F17: 2.039 | G17: 316 | H17: 297
A18: EU27 | B18: Finland | C18: 5.366 | D18: 2.077 | E18: 14292 | F18: 1.468 | G18: 771 | H18: 1053
A19: EU27 | B19: France | C19: 63.027 | D19: 3.848 | E19: 309977 | F19: 2.73 | G19: 15365 | H19: 20460
A20: EU27 | B20: Germany | C20: 80.895 | D20: 3.667 | E20: 377130 | F20: 2.593 | G20: 23223 | H20: 27599
A21: EU27 | B21: Greece | C21: 11.446 | D21: 5.473 | E21: 71291 | F21: 3.932 | G21: 4344 | H21: 5256
... A36: EU27 | B36: Sweden | C36: 9.39 | D36: 2.308 | E36: 25864 | F36: 1.509 | G36: 1587 | H36: 1902
A37: EU27 Total | C37: 440.529 | D37: 4.198 | E37: 2306258 | F37: 3.048 | G37: 135875 | H37: 165363
A38: NON EU27 | B38: Albania | C38: 2.941 | D38: 7.81 | E38: 23459 | F38: 5.94 | G38: 1120 | H38: 1772
A39: NON EU27 | B39: Armenia | C39: 2.877 | D39: 7.762 | E39: 26843 | F39: 7.016 | G39: 1579 | H39: 1864
A40: NON EU27 | B40: Azerbaijan | C40: 9.032 | D40: 5.732 | E40: 64264 | F40: 5.1 | G40: 2148 | H40: 4502
A41: NON EU27 | B41: Belarus | C41: 9.473 | D41: 4.656 | E41: 62274 | F41: 4.286 | G41: 4982 | H41: 4358
A42: NON EU27 | B42: Bosnia and Herzegovina | C42: 3.722 | D42: 8.37 | E42: 36752 | F42: 6.952 | G42: 2184 | H42: 2743
A43: NON EU27 | B43: Georgia | C43: 4.232 | D43: 6.104 | E43: 28296 | F43: 5.126 | G43: 2242 | H43: 2192
A44: NON EU27 | B44: Iceland | C44: 0.32 | D44: 2.697 | E44: 901 | F44: 1.809 | G44: 39 | H44: 64
A45: NON EU27 | B45: Kazakhstan | C45: 16.399 | D45: 13.716 | E45: 292249 | F45: 12.752 | G45: 15279 | H45: 19958
A46: NON EU27 | B46: Kosovo | C46: 1.827 | D46: 13.196 | E46: 10243 | F46: 10.426 | G46: 811 | H46: 827
A47: NON EU27 | B47: Kyrgyzstan | C47: 5.422 | D47: 7.204 | E47: 42853 | F47: 6.488 | G47: 1847 | H47: 2789
A48: NON EU27 | B48: North Macedonia | C48: 2.071 | D48: 7.744 | E48: 17917 | F48: 6.118 | G48: 1104 | H48: 1446
A49: NON EU27 | B49: Republic of Moldova | C49: 4.084 | D49: 6.431 | E49: 34398 | F49: 5.751 | G49: 2354 | H49: 2578
... A60: NON EU27 | B60: Uzbekistan | C60: 28.606 | D60: 8.13 | E60: 275098 | F60: 7.663 | G60: 8091 | H60: 17330
A61: NON EU27 Total | C61: 411.759 | D61: 6.483 | E61: 3286853 | F61: 5.613 | G61: 190368 | H61: 227864

Sheet yoll_Europe (6)
A2: Premature mortality due to PM2.5
A3: Scenario: A1r/s/D/v5a
A4: Region:
A5: Year: 2040
A6: Unit: -,mln people, μg/m3, mln years,cases,cases
A7: UserID: StefanA
C9: Total Population (2010) | D9: Mean PM<sub>2.5</sub><br>concentration | E9: YOLL | F9: Months lost | G9: Premature deaths static | H9: Premature deaths
A10: EU27 | B10: Austria | C10: 8.41 | D10: 3.923 | E10: 40582 | F10: 2.698 | G10: 2256 | H10: 2921
A11: EU27 | B11: Belgium | C11: 10.939 | D11: 5.033 | E11: 67635 | F11: 3.558 | G11: 3973 | H11: 4739
A12: EU27 | B12: Bulgaria | C12: 7.405 | D12: 5.01 | E12: 46736 | F12: 4.044 | G12: 4178 | H12: 3804
A13: EU27 | B13: Croatia | C13: 4.328 | D13: 4.94 | E13: 25760 | F13: 3.989 | G13: 1908 | H13: 1965
A14: EU27 | B14: Cyprus | C14: 1.113 | D14: 6.108 | E14: 7324 | F14: 4.462 | G14: 331 | H14: 532
A15: EU27 | B15: Czech Republic | C15: 10.536 | D15: 4.801 | E15: 64032 | F15: 3.734 | G15: 3842 | H15: 4819
A16: EU27 | B16: Denmark | C16: 5.555 | D16: 3.327 | E16: 23248 | F16: 2.465 | G16: 1383 | H16: 1690
A17: EU27 | B17: Estonia | C17: 1.332 | D17: 2.901 | E17: 4880 | F17: 2.378 | G17: 369 | H17: 347
A18: EU27 | B18: Finland | C18: 5.366 | D18: 2.369 | E18: 16302 | F18: 1.674 | G18: 880 | H18: 1201
A19: EU27 | B19: France | C19: 63.027 | D19: 4.296 | E19: 346075 | F19: 3.048 | G19: 17155 | H19: 22842
A20: EU27 | B20: Germany | C20: 80.895 | D20: 4.106 | E20: 422253 | F20: 2.904 | G20: 26002 | H20: 30901
A21: EU27 | B21: Greece | C21: 11.446 | D21: 6.15 | E21: 80109 | F21: 4.418 | G21: 4881 | H21: 5907
... A36: EU27 | B36: Sweden | C36: 9.39 | D36: 2.525 | E36: 28299 | F36: 1.651 | G36: 1736 | H36: 2081
A37: EU27 Total | C37: 440.529 | D37: 4.752 | E37: 2612507 | F37: 3.463 | G37: 154406 | H37: 187403
A38: NON EU27 | B38: Albania | C38: 2.941 | D38: 10.246 | E38: 30779 | F38: 7.793 | G38: 1469 | H38: 2325
A39: NON EU27 | B39: Armenia | C39: 2.877 | D39: 9.427 | E39: 32598 | F39: 8.52 | G39: 1917 | H39: 2264
A40: NON EU27 | B40: Azerbaijan | C40: 9.032 | D40: 6.361 | E40: 71307 | F40: 5.659 | G40: 2383 | H40: 4996
A41: NON EU27 | B41: Belarus | C41: 9.473 | D41: 6.305 | E41: 84341 | F41: 5.805 | G41: 6748 | H41: 5902
A42: NON EU27 | B42: Bosnia and Herzegovina | C42: 3.722 | D42: 11.975 | E42: 52583 | F42: 9.947 | G42: 3124 | H42: 3925
A43: NON EU27 | B43: Georgia | C43: 4.232 | D43: 8.384 | E43: 38864 | F43: 7.04 | G43: 3079 | H43: 3010
A44: NON EU27 | B44: Iceland | C44: 0.32 | D44: 3.022 | E44: 1010 | F44: 2.027 | G44: 44 | H44: 71
A45: NON EU27 | B45: Kazakhstan | C45: 16.399 | D45: 16.156 | E45: 344236 | F45: 15.02 | G45: 17997 | H45: 23509
A46: NON EU27 | B46: Kosovo | C46: 1.827 | D46: 19.719 | E46: 15306 | F46: 15.579 | G46: 1212 | H46: 1235
A47: NON EU27 | B47: Kyrgyzstan | C47: 5.422 | D47: 10.634 | E47: 63255 | F47: 9.577 | G47: 2726 | H47: 4117
A48: NON EU27 | B48: North Macedonia | C48: 2.071 | D48: 10.431 | E48: 24133 | F48: 8.241 | G48: 1487 | H48: 1947
A49: NON EU27 | B49: Republic of Moldova | C49: 4.084 | D49: 8.584 | E49: 45914 | F49: 7.676 | G49: 3142 | H49: 3441
... A60: NON EU27 | B60: Uzbekistan | C60: 28.606 | D60: 9.652 | E60: 326613 | F60: 9.098 | G60: 9606 | H60: 20576
A61: NON EU27 Total | C61: 411.759 | D61: 7.983 | E61: 4048919 | F61: 6.933 | G61: 236664 | H61: 281055

Sheet yoll_Europe (7)
A2: Premature mortality due to PM2.5
A3: Scenario: A1r/s/G/v5a
A4: Region:
A5: Year: 2040
A6: Unit: -,mln people, μg/m3, mln years,cases,cases
A7: UserID: StefanA
C9: Total Population (2010) | D9: Mean PM<sub>2.5</sub><br>concentration | E9: YOLL | F9: Months lost | G9: Premature deaths static | H9: Premature deaths
A10: EU27 | B10: Austria | C10: 8.41 | D10: 3.811 | E10: 39429 | F10: 2.621 | G10: 2192 | H10: 2838
A11: EU27 | B11: Belgium | C11: 10.939 | D11: 4.976 | E11: 66876 | F11: 3.518 | G11: 3928 | H11: 4685
A12: EU27 | B12: Bulgaria | C12: 7.405 | D12: 4.923 | E12: 45928 | F12: 3.974 | G12: 4106 | H12: 3739
A13: EU27 | B13: Croatia | C13: 4.328 | D13: 4.695 | E13: 24480 | F13: 3.791 | G13: 1813 | H13: 1868
A14: EU27 | B14: Cyprus | C14: 1.113 | D14: 6.067 | E14: 7275 | F14: 4.432 | G14: 329 | H14: 529
A15: EU27 | B15: Czech Republic | C15: 10.536 | D15: 4.626 | E15: 61707 | F15: 3.598 | G15: 3702 | H15: 4644
A16: EU27 | B16: Denmark | C16: 5.555 | D16: 3.222 | E16: 22516 | F16: 2.388 | G16: 1339 | H16: 1637
A17: EU27 | B17: Estonia | C17: 1.332 | D17: 2.808 | E17: 4722 | F17: 2.301 | G17: 357 | H17: 336
A18: EU27 | B18: Finland | C18: 5.366 | D18: 2.295 | E18: 15791 | F18: 1.622 | G18: 852 | H18: 1163
A19: EU27 | B19: France | C19: 63.027 | D19: 4.187 | E19: 337322 | F19: 2.971 | G19: 16721 | H19: 22265
A20: EU27 | B20: Germany | C20: 80.895 | D20: 4.054 | E20: 416915 | F20: 2.867 | G20: 25673 | H20: 30511
A21: EU27 | B21: Greece | C21: 11.446 | D21: 6.062 | E21: 78954 | F21: 4.354 | G21: 4811 | H21: 5821
... A36: EU27 | B36: Sweden | C36: 9.39 | D36: 2.47 | E36: 27678 | F36: 1.615 | G36: 1698 | H36: 2035
A37: EU27 Total | C37: 440.529 | D37: 4.644 | E37: 2552743 | F37: 3.381 | G37: 150842 | H37: 183133
A38: NON EU27 | B38: Albania | C38: 2.941 | D38: 9.628 | E38: 28923 | F38: 7.323 | G38: 1381 | H38: 2185
A39: NON EU27 | B39: Armenia | C39: 2.877 | D39: 9.456 | E39: 32701 | F39: 8.547 | G39: 1923 | H39: 2271
A40: NON EU27 | B40: Azerbaijan | C40: 9.032 | D40: 6.33 | E40: 70966 | F40: 5.632 | G40: 2372 | H40: 4972
A41: NON EU27 | B41: Belarus | C41: 9.473 | D41: 6.087 | E41: 81424 | F41: 5.604 | G41: 6514 | H41: 5698
A42: NON EU27 | B42: Bosnia and Herzegovina | C42: 3.722 | D42: 10.724 | E42: 47090 | F42: 8.908 | G42: 2798 | H42: 3515
A43: NON EU27 | B43: Georgia | C43: 4.232 | D43: 7.795 | E43: 36132 | F43: 6.545 | G43: 2863 | H43: 2799
A44: NON EU27 | B44: Iceland | C44: 0.32 | D44: 2.934 | E44: 981 | F44: 1.969 | G44: 43 | H44: 69
A45: NON EU27 | B45: Kazakhstan | C45: 16.399 | D45: 16.161 | E45: 344360 | F45: 15.026 | G45: 18003 | H45: 23517
A46: NON EU27 | B46: Kosovo | C46: 1.827 | D46: 17.161 | E46: 13320 | F46: 13.558 | G46: 1055 | H46: 1075
A47: NON EU27 | B47: Kyrgyzstan | C47: 5.422 | D47: 9.963 | E47: 59268 | F47: 8.973 | G47: 2554 | H47: 3857
A48: NON EU27 | B48: North Macedonia | C48: 2.071 | D48: 9.588 | E48: 22183 | F48: 7.575 | G48: 1367 | H48: 1790
A49: NON EU27 | B49: Republic of Moldova | C49: 4.084 | D49: 8.128 | E49: 43475 | F49: 7.269 | G49: 2975 | H49: 3258
... A60: NON EU27 | B60: Uzbekistan | C60: 28.606 | D60: 10.011 | E60: 338756 | F60: 9.437 | G60: 9963 | H60: 21341
A61: NON EU27 Total | C61: 411.759 | D61: 8.055 | E61: 4093075 | F61: 6.999 | G61: 238887 | H61: 283883

Sheet yoll_Europe (8)
A2: Premature mortality due to PM2.5
A3: Scenario: A2/d/D/v5a
A4: Region:
A5: Year: 2040
A6: Unit: -,mln people, μg/m3, mln years,cases,cases
A7: UserID: StefanA
C9: Total Population (2010) | D9: Mean PM<sub>2.5</sub><br>concentration | E9: YOLL | F9: Months lost | G9: Premature deaths static | H9: Premature deaths
A10: EU27 | B10: Austria | C10: 8.41 | D10: 3.24 | E10: 33520 | F10: 2.228 | G10: 1863 | H10: 2413
A11: EU27 | B11: Belgium | C11: 10.939 | D11: 4.208 | E11: 56551 | F11: 2.975 | G11: 3322 | H11: 3962
A12: EU27 | B12: Bulgaria | C12: 7.405 | D12: 3.498 | E12: 32632 | F12: 2.824 | G12: 2917 | H12: 2656
A13: EU27 | B13: Croatia | C13: 4.328 | D13: 3.66 | E13: 19083 | F13: 2.955 | G13: 1414 | H13: 1456
A14: EU27 | B14: Cyprus | C14: 1.113 | D14: 5.034 | E14: 6035 | F14: 3.677 | G14: 273 | H14: 439
A15: EU27 | B15: Czech Republic | C15: 10.536 | D15: 3.802 | E15: 50710 | F15: 2.957 | G15: 3042 | H15: 3816
A16: EU27 | B16: Denmark | C16: 5.555 | D16: 2.84 | E16: 19849 | F16: 2.105 | G16: 1181 | H16: 1443
A17: EU27 | B17: Estonia | C17: 1.332 | D17: 2.453 | E17: 4127 | F17: 2.011 | G17: 312 | H17: 293
A18: EU27 | B18: Finland | C18: 5.366 | D18: 2.026 | E18: 13938 | F18: 1.431 | G18: 752 | H18: 1027
A19: EU27 | B19: France | C19: 63.027 | D19: 3.685 | E19: 296877 | F19: 2.614 | G19: 14716 | H19: 19595
A20: EU27 | B20: Germany | C20: 80.895 | D20: 3.461 | E20: 355962 | F20: 2.448 | G20: 21920 | H20: 26050
A21: EU27 | B21: Greece | C21: 11.446 | D21: 5.22 | E21: 67989 | F21: 3.75 | G21: 4143 | H21: 5013
... A36: EU27 | B36: Sweden | C36: 9.39 | D36: 2.253 | E36: 25255 | F36: 1.474 | G36: 1549 | H36: 1857
A37: EU27 Total | C37: 440.529 | D37: 3.972 | E37: 2180754 | F37: 2.877 | G37: 128170 | H37: 156296
A38: NON EU27 | B38: Albania | C38: 2.941 | D38: 6.673 | E38: 20044 | F38: 5.075 | G38: 957 | H38: 1514
A39: NON EU27 | B39: Armenia | C39: 2.877 | D39: 5.966 | E39: 20630 | F39: 5.392 | G39: 1213 | H39: 1433
A40: NON EU27 | B40: Azerbaijan | C40: 9.032 | D40: 4.871 | E40: 54602 | F40: 4.334 | G40: 1825 | H40: 3825
A41: NON EU27 | B41: Belarus | C41: 9.473 | D41: 3.976 | E41: 53184 | F41: 3.661 | G41: 4255 | H41: 3722
A42: NON EU27 | B42: Bosnia and Herzegovina | C42: 3.722 | D42: 7.094 | E42: 31151 | F42: 5.893 | G42: 1851 | H42: 2325
A43: NON EU27 | B43: Georgia | C43: 4.232 | D43: 5.193 | E43: 24073 | F43: 4.361 | G43: 1907 | H43: 1865
A44: NON EU27 | B44: Iceland | C44: 0.32 | D44: 2.588 | E44: 865 | F44: 1.737 | G44: 37 | H44: 61
A45: NON EU27 | B45: Kazakhstan | C45: 16.399 | D45: 12.797 | E45: 272677 | F45: 11.898 | G45: 14256 | H45: 18622
A46: NON EU27 | B46: Kosovo | C46: 1.827 | D46: 11.11 | E46: 8623 | F46: 8.777 | G46: 683 | H46: 696
A47: NON EU27 | B47: Kyrgyzstan | C47: 5.422 | D47: 5.466 | E47: 32515 | F47: 4.923 | G47: 1401 | H47: 2116
A48: NON EU27 | B48: North Macedonia | C48: 2.071 | D48: 6.762 | E48: 15645 | F48: 5.343 | G48: 964 | H48: 1262
A49: NON EU27 | B49: Republic of Moldova | C49: 4.084 | D49: 5.536 | E49: 29608 | F49: 4.95 | G49: 2026 | H49: 2219
... A60: NON EU27 | B60: Uzbekistan | C60: 28.606 | D60: 7.134 | E60: 241419 | F60: 6.725 | G60: 7100 | H60: 15209
A61: NON EU27 Total | C61: 411.759 | D61: 5.591 | E61: 2836792 | F61: 4.833 | G61: 163923 | H61: 196658

Sheet yoll_Europe (9)
A2: Premature mortality due to PM2.5
A3: Scenario: A2/s/D/v5a
A4: Region:
A5: Year: 2040
A6: Unit: -,mln people, μg/m3, mln years,cases,cases
A7: UserID: StefanA
C9: Total Population (2010) | D9: Mean PM<sub>2.5</sub><br>concentration | E9: YOLL | F9: Months lost | G9: Premature deaths static | H9: Premature deaths
A10: EU27 | B10: Austria | C10: 8.41 | D10: 3.644 | E10: 37694 | F10: 2.506 | G10: 2095 | H10: 2713
A11: EU27 | B11: Belgium | C11: 10.939 | D11: 4.69 | E11: 63030 | F11: 3.316 | G11: 3703 | H11: 4416
A12: EU27 | B12: Bulgaria | C12: 7.405 | D12: 4.332 | E12: 40409 | F12: 3.497 | G12: 3612 | H12: 3289
A13: EU27 | B13: Croatia | C13: 4.328 | D13: 4.353 | E13: 22697 | F13: 3.514 | G13: 1681 | H13: 1732
A14: EU27 | B14: Cyprus | C14: 1.113 | D14: 5.658 | E14: 6784 | F14: 4.134 | G14: 307 | H14: 493
A15: EU27 | B15: Czech Republic | C15: 10.536 | D15: 4.388 | E15: 58526 | F15: 3.413 | G15: 3511 | H15: 4405
A16: EU27 | B16: Denmark | C16: 5.555 | D16: 3.129 | E16: 21866 | F16: 2.319 | G16: 1301 | H16: 1589
A17: EU27 | B17: Estonia | C17: 1.332 | D17: 2.71 | E17: 4558 | F17: 2.221 | G17: 345 | H17: 324
A18: EU27 | B18: Finland | C18: 5.366 | D18: 2.215 | E18: 15242 | F18: 1.565 | G18: 822 | H18: 1123
A19: EU27 | B19: France | C19: 63.027 | D19: 3.94 | E19: 317430 | F19: 2.795 | G19: 15735 | H19: 20952
A20: EU27 | B20: Germany | C20: 80.895 | D20: 3.839 | E20: 394820 | F20: 2.715 | G20: 24312 | H20: 28894
A21: EU27 | B21: Greece | C21: 11.446 | D21: 5.704 | E21: 74300 | F21: 4.098 | G21: 4527 | H21: 5478
... A36: EU27 | B36: Sweden | C36: 9.39 | D36: 2.411 | E36: 27017 | F36: 1.576 | G36: 1658 | H36: 1987
A37: EU27 Total | C37: 440.529 | D37: 4.423 | E37: 2430040 | F37: 3.216 | G37: 143392 | H37: 174283
A38: NON EU27 | B38: Albania | C38: 2.941 | D38: 9.089 | E38: 27303 | F38: 6.913 | G38: 1303 | H38: 2063
A39: NON EU27 | B39: Armenia | C39: 2.877 | D39: 9.055 | E39: 31314 | F39: 8.185 | G39: 1842 | H39: 2175
A40: NON EU27 | B40: Azerbaijan | C40: 9.032 | D40: 5.983 | E40: 67075 | F40: 5.324 | G40: 2242 | H40: 4699
A41: NON EU27 | B41: Belarus | C41: 9.473 | D41: 5.653 | E41: 75609 | F41: 5.204 | G41: 6049 | H41: 5291
A42: NON EU27 | B42: Bosnia and Herzegovina | C42: 3.722 | D42: 9.925 | E42: 43580 | F42: 8.244 | G42: 2589 | H42: 3253
A43: NON EU27 | B43: Georgia | C43: 4.232 | D43: 7.896 | E43: 36602 | F43: 6.63 | G43: 2900 | H43: 2835
A44: NON EU27 | B44: Iceland | C44: 0.32 | D44: 2.659 | E44: 889 | F44: 1.784 | G44: 39 | H44: 63
A45: NON EU27 | B45: Kazakhstan | C45: 16.399 | D45: 15.216 | E45: 324208 | F45: 14.146 | G45: 16950 | H45: 22141
A46: NON EU27 | B46: Kosovo | C46: 1.827 | D46: 17.64 | E46: 13692 | F46: 13.937 | G46: 1084 | H46: 1105
A47: NON EU27 | B47: Kyrgyzstan | C47: 5.422 | D47: 9.357 | E47: 55659 | F47: 8.427 | G47: 2398 | H47: 3622
A48: NON EU27 | B48: North Macedonia | C48: 2.071 | D48: 9.775 | E48: 22615 | F48: 7.723 | G48: 1393 | H48: 1825
A49: NON EU27 | B49: Republic of Moldova | C49: 4.084 | D49: 7.72 | E49: 41290 | F49: 6.903 | G49: 2826 | H49: 3095
... A60: NON EU27 | B60: Uzbekistan | C60: 28.606 | D60: 8.97 | E60: 303532 | F60: 8.455 | G60: 8927 | H60: 19122
A61: NON EU27 Total | C61: 411.759 | D61: 7.087 | E61: 3578953 | F61: 6.137 | G61: 206627 | H61: 248101

Sheet yoll_Europe (10)
A2: Premature mortality due to PM2.5
A3: Scenario: A3/d/D/v5a
A4: Region:
A5: Year: 2040
A6: Unit: -,mln people, μg/m3, mln years,cases,cases
A7: UserID: StefanA
C9: Total Population (2010) | D9: Mean PM<sub>2.5</sub><br>concentration | E9: YOLL | F9: Months lost | G9: Premature deaths static | H9: Premature deaths
A10: EU27 | B10: Austria | C10: 8.41 | D10: 3.24 | E10: 33520 | F10: 2.228 | G10: 1863 | H10: 2413
A11: EU27 | B11: Belgium | C11: 10.939 | D11: 4.208 | E11: 56551 | F11: 2.975 | G11: 3322 | H11: 3962
A12: EU27 | B12: Bulgaria | C12: 7.405 | D12: 3.498 | E12: 32632 | F12: 2.824 | G12: 2917 | H12: 2656
A13: EU27 | B13: Croatia | C13: 4.328 | D13: 3.66 | E13: 19083 | F13: 2.955 | G13: 1414 | H13: 1456
A14: EU27 | B14: Cyprus | C14: 1.113 | D14: 5.034 | E14: 6035 | F14: 3.677 | G14: 273 | H14: 439
A15: EU27 | B15: Czech Republic | C15: 10.536 | D15: 3.802 | E15: 50710 | F15: 2.957 | G15: 3042 | H15: 3816
A16: EU27 | B16: Denmark | C16: 5.555 | D16: 2.84 | E16: 19849 | F16: 2.105 | G16: 1181 | H16: 1443
A17: EU27 | B17: Estonia | C17: 1.332 | D17: 2.453 | E17: 4127 | F17: 2.011 | G17: 312 | H17: 293
A18: EU27 | B18: Finland | C18: 5.366 | D18: 2.026 | E18: 13938 | F18: 1.431 | G18: 752 | H18: 1027
A19: EU27 | B19: France | C19: 63.027 | D19: 3.685 | E19: 296877 | F19: 2.614 | G19: 14716 | H19: 19595
A20: EU27 | B20: Germany | C20: 80.895 | D20: 3.461 | E20: 355962 | F20: 2.448 | G20: 21920 | H20: 26050
A21: EU27 | B21: Greece | C21: 11.446 | D21: 5.22 | E21: 67989 | F21: 3.75 | G21: 4143 | H21: 5013
... A36: EU27 | B36: Sweden | C36: 9.39 | D36: 2.253 | E36: 25255 | F36: 1.474 | G36: 1549 | H36: 1857
A37: EU27 Total | C37: 440.529 | D37: 3.972 | E37: 2180754 | F37: 2.877 | G37: 128170 | H37: 156296
A38: NON EU27 | B38: Albania | C38: 2.941 | D38: 6.673 | E38: 20044 | F38: 5.075 | G38: 957 | H38: 1514
A39: NON EU27 | B39: Armenia | C39: 2.877 | D39: 5.966 | E39: 20630 | F39: 5.392 | G39: 1213 | H39: 1433
A40: NON EU27 | B40: Azerbaijan | C40: 9.032 | D40: 4.871 | E40: 54602 | F40: 4.334 | G40: 1825 | H40: 3825
A41: NON EU27 | B41: Belarus | C41: 9.473 | D41: 3.976 | E41: 53184 | F41: 3.661 | G41: 4255 | H41: 3722
A42: NON EU27 | B42: Bosnia and Herzegovina | C42: 3.722 | D42: 7.094 | E42: 31151 | F42: 5.893 | G42: 1851 | H42: 2325
A43: NON EU27 | B43: Georgia | C43: 4.232 | D43: 5.193 | E43: 24073 | F43: 4.361 | G43: 1907 | H43: 1865
A44: NON EU27 | B44: Iceland | C44: 0.32 | D44: 2.588 | E44: 865 | F44: 1.737 | G44: 37 | H44: 61
A45: NON EU27 | B45: Kazakhstan | C45: 16.399 | D45: 12.797 | E45: 272677 | F45: 11.898 | G45: 14256 | H45: 18622
A46: NON EU27 | B46: Kosovo | C46: 1.827 | D46: 11.11 | E46: 8623 | F46: 8.777 | G46: 683 | H46: 696
A47: NON EU27 | B47: Kyrgyzstan | C47: 5.422 | D47: 5.466 | E47: 32515 | F47: 4.923 | G47: 1401 | H47: 2116
A48: NON EU27 | B48: North Macedonia | C48: 2.071 | D48: 6.762 | E48: 15645 | F48: 5.343 | G48: 964 | H48: 1262
A49: NON EU27 | B49: Republic of Moldova | C49: 4.084 | D49: 5.536 | E49: 29608 | F49: 4.95 | G49: 2026 | H49: 2219
... A60: NON EU27 | B60: Uzbekistan | C60: 28.606 | D60: 7.134 | E60: 241419 | F60: 6.725 | G60: 7100 | H60: 15209
A61: NON EU27 Total | C61: 411.759 | D61: 5.591 | E61: 2836792 | F61: 4.833 | G61: 163923 | H61: 196658

Sheet yoll_Europe (11)
A2: Premature mortality due to PM2.5
A3: Scenario: A3/s/D/v5a
A4: Region:
A5: Year: 2040
A6: Unit: -,mln people, μg/m3, mln years,cases,cases
A7: UserID: StefanA
C9: Total Population (2010) | D9: Mean PM<sub>2.5</sub><br>concentration | E9: YOLL | F9: Months lost | G9: Premature deaths static | H9: Premature deaths
A10: EU27 | B10: Austria | C10: 8.41 | D10: 3.644 | E10: 37694 | F10: 2.506 | G10: 2095 | H10: 2713
A11: EU27 | B11: Belgium | C11: 10.939 | D11: 4.69 | E11: 63030 | F11: 3.316 | G11: 3703 | H11: 4416
A12: EU27 | B12: Bulgaria | C12: 7.405 | D12: 4.332 | E12: 40409 | F12: 3.497 | G12: 3612 | H12: 3289
A13: EU27 | B13: Croatia | C13: 4.328 | D13: 4.353 | E13: 22697 | F13: 3.514 | G13: 1681 | H13: 1732
A14: EU27 | B14: Cyprus | C14: 1.113 | D14: 5.658 | E14: 6784 | F14: 4.134 | G14: 307 | H14: 493
A15: EU27 | B15: Czech Republic | C15: 10.536 | D15: 4.388 | E15: 58526 | F15: 3.413 | G15: 3511 | H15: 4405
A16: EU27 | B16: Denmark | C16: 5.555 | D16: 3.129 | E16: 21866 | F16: 2.319 | G16: 1301 | H16: 1589
A17: EU27 | B17: Estonia | C17: 1.332 | D17: 2.71 | E17: 4558 | F17: 2.221 | G17: 345 | H17: 324
A18: EU27 | B18: Finland | C18: 5.366 | D18: 2.215 | E18: 15242 | F18: 1.565 | G18: 822 | H18: 1123
A19: EU27 | B19: France | C19: 63.027 | D19: 3.94 | E19: 317430 | F19: 2.795 | G19: 15735 | H19: 20952
A20: EU27 | B20: Germany | C20: 80.895 | D20: 3.839 | E20: 394820 | F20: 2.715 | G20: 24312 | H20: 28894
A21: EU27 | B21: Greece | C21: 11.446 | D21: 5.704 | E21: 74300 | F21: 4.098 | G21: 4527 | H21: 5478
... A36: EU27 | B36: Sweden | C36: 9.39 | D36: 2.411 | E36: 27017 | F36: 1.576 | G36: 1658 | H36: 1987
A37: EU27 Total | C37: 440.529 | D37: 4.423 | E37: 2430040 | F37: 3.216 | G37: 143392 | H37: 174283
A38: NON EU27 | B38: Albania | C38: 2.941 | D38: 9.089 | E38: 27303 | F38: 6.913 | G38: 1303 | H38: 2063
A39: NON EU27 | B39: Armenia | C39: 2.877 | D39: 9.055 | E39: 31314 | F39: 8.185 | G39: 1842 | H39: 2175
A40: NON EU27 | B40: Azerbaijan | C40: 9.032 | D40: 5.983 | E40: 67075 | F40: 5.324 | G40: 2242 | H40: 4699
A41: NON EU27 | B41: Belarus | C41: 9.473 | D41: 5.653 | E41: 75609 | F41: 5.204 | G41: 6049 | H41: 5291
A42: NON EU27 | B42: Bosnia and Herzegovina | C42: 3.722 | D42: 9.925 | E42: 43580 | F42: 8.244 | G42: 2589 | H42: 3253
A43: NON EU27 | B43: Georgia | C43: 4.232 | D43: 7.896 | E43: 36602 | F43: 6.63 | G43: 2900 | H43: 2835
A44: NON EU27 | B44: Iceland | C44: 0.32 | D44: 2.659 | E44: 889 | F44: 1.784 | G44: 39 | H44: 63
A45: NON EU27 | B45: Kazakhstan | C45: 16.399 | D45: 15.216 | E45: 324208 | F45: 14.146 | G45: 16950 | H45: 22141
A46: NON EU27 | B46: Kosovo | C46: 1.827 | D46: 17.64 | E46: 13692 | F46: 13.937 | G46: 1084 | H46: 1105
A47: NON EU27 | B47: Kyrgyzstan | C47: 5.422 | D47: 9.357 | E47: 55659 | F47: 8.427 | G47: 2398 | H47: 3622
A48: NON EU27 | B48: North Macedonia | C48: 2.071 | D48: 9.775 | E48: 22615 | F48: 7.723 | G48: 1393 | H48: 1825
A49: NON EU27 | B49: Republic of Moldova | C49: 4.084 | D49: 7.72 | E49: 41290 | F49: 6.903 | G49: 2826 | H49: 3095
... A60: NON EU27 | B60: Uzbekistan | C60: 28.606 | D60: 8.97 | E60: 303532 | F60: 8.455 | G60: 8927 | H60: 19122
A61: NON EU27 Total | C61: 411.759 | D61: 7.087 | E61: 3578953 | F61: 6.137 | G61: 206627 | H61: 248101

Sheet yoll_Europe (12)
A2: Premature mortality due to PM2.5
A3: Scenario: A4/s/D/v5a
A4: Region:
A5: Year: 2040
A6: Unit: -,mln people, μg/m3, mln years,cases,cases
A7: UserID: StefanA
C9: Total Population (2010) | D9: Mean PM<sub>2.5</sub><br>concentration | E9: YOLL | F9: Months lost | G9: Premature deaths static | H9: Premature deaths
A10: EU27 | B10: Austria | C10: 8.41 | D10: 3.45 | E10: 35696 | F10: 2.373 | G10: 1984 | H10: 2569
A11: EU27 | B11: Belgium | C11: 10.939 | D11: 4.322 | E11: 58082 | F11: 3.056 | G11: 3412 | H11: 4069
A12: EU27 | B12: Bulgaria | C12: 7.405 | D12: 3.619 | E12: 33761 | F12: 2.921 | G12: 3018 | H12: 2748
A13: EU27 | B13: Croatia | C13: 4.328 | D13: 3.971 | E13: 20705 | F13: 3.206 | G13: 1534 | H13: 1580
A14: EU27 | B14: Cyprus | C14: 1.113 | D14: 5.215 | E14: 6253 | F14: 3.81 | G14: 283 | H14: 455
A15: EU27 | B15: Czech Republic | C15: 10.536 | D15: 4.14 | E15: 55212 | F15: 3.219 | G15: 3313 | H15: 4155
A16: EU27 | B16: Denmark | C16: 5.555 | D16: 2.917 | E16: 20381 | F16: 2.161 | G16: 1212 | H16: 1481
A17: EU27 | B17: Estonia | C17: 1.332 | D17: 2.547 | E17: 4284 | F17: 2.088 | G17: 324 | H17: 305
A18: EU27 | B18: Finland | C18: 5.366 | D18: 2.101 | E18: 14456 | F18: 1.484 | G18: 780 | H18: 1065
A19: EU27 | B19: France | C19: 63.027 | D19: 3.8 | E19: 306121 | F19: 2.696 | G19: 15174 | H19: 20205
A20: EU27 | B20: Germany | C20: 80.895 | D20: 3.567 | E20: 366833 | F20: 2.523 | G20: 22589 | H20: 26846
A21: EU27 | B21: Greece | C21: 11.446 | D21: 5.369 | E21: 69937 | F21: 3.857 | G21: 4261 | H21: 5157
... A36: EU27 | B36: Sweden | C36: 9.39 | D36: 2.307 | E36: 25862 | F36: 1.509 | G36: 1587 | H36: 1902
A37: EU27 Total | C37: 440.529 | D37: 4.136 | E37: 2271516 | F37: 3 | G37: 133512 | H37: 162790
A38: NON EU27 | B38: Albania | C38: 2.941 | D38: 7.151 | E38: 21480 | F38: 5.439 | G38: 1025 | H38: 1623
A39: NON EU27 | B39: Armenia | C39: 2.877 | D39: 6.231 | E39: 21548 | F39: 5.632 | G39: 1267 | H39: 1497
A40: NON EU27 | B40: Azerbaijan | C40: 9.032 | D40: 5.354 | E40: 60023 | F40: 4.764 | G40: 2006 | H40: 4205
A41: NON EU27 | B41: Belarus | C41: 9.473 | D41: 4.775 | E41: 63869 | F41: 4.396 | G41: 5110 | H41: 4469
A42: NON EU27 | B42: Bosnia and Herzegovina | C42: 3.722 | D42: 7.264 | E42: 31895 | F42: 6.033 | G42: 1895 | H42: 2381
A43: NON EU27 | B43: Georgia | C43: 4.232 | D43: 5.452 | E43: 25270 | F43: 4.578 | G43: 2002 | H43: 1957
A44: NON EU27 | B44: Iceland | C44: 0.32 | D44: 2.613 | E44: 873 | F44: 1.753 | G44: 38 | H44: 62
A45: NON EU27 | B45: Kazakhstan | C45: 16.399 | D45: 13.693 | E45: 291772 | F45: 12.731 | G45: 15254 | H45: 19926
A46: NON EU27 | B46: Kosovo | C46: 1.827 | D46: 11.243 | E46: 8726 | F46: 8.882 | G46: 691 | H46: 704
A47: NON EU27 | B47: Kyrgyzstan | C47: 5.422 | D47: 6.29 | E47: 37418 | F47: 5.665 | G47: 1612 | H47: 2435
A48: NON EU27 | B48: North Macedonia | C48: 2.071 | D48: 6.949 | E48: 16077 | F48: 5.49 | G48: 991 | H48: 1297
A49: NON EU27 | B49: Republic of Moldova | C49: 4.084 | D49: 6.974 | E49: 37303 | F49: 6.237 | G49: 2553 | H49: 2796
... A60: NON EU27 | B60: Uzbekistan | C60: 28.606 | D60: 7.838 | E60: 265236 | F60: 7.389 | G60: 7801 | H60: 16709
A61: NON EU27 Total | C61: 411.759 | D61: 6.047 | E61: 3072484 | F61: 5.238 | G61: 177019 | H61: 212836

Sheet yoll_Europe (13)
A2: Premature mortality due to PM2.5
A3: Scenario: B1/d/D/v5a
A4: Region:
A5: Year: 2040
A6: Unit: -,mln people, μg/m3, mln years,cases,cases
A7: UserID: StefanA
C9: Total Population (2010) | D9: Mean PM<sub>2.5</sub><br>concentration | E9: YOLL | F9: Months lost | G9: Premature deaths static | H9: Premature deaths
A10: EU27 | B10: Austria | C10: 8.41 | D10: 3.532 | E10: 36538 | F10: 2.429 | G10: 2031 | H10: 2630
A11: EU27 | B11: Belgium | C11: 10.939 | D11: 4.463 | E11: 59978 | F11: 3.156 | G11: 3523 | H11: 4202
A12: EU27 | B12: Bulgaria | C12: 7.405 | D12: 3.976 | E12: 37090 | F12: 3.21 | G12: 3316 | H12: 3019
A13: EU27 | B13: Croatia | C13: 4.328 | D13: 4.156 | E13: 21671 | F13: 3.356 | G13: 1605 | H13: 1653
A14: EU27 | B14: Cyprus | C14: 1.113 | D14: 5.227 | E14: 6267 | F14: 3.819 | G14: 283 | H14: 456
A15: EU27 | B15: Czech Republic | C15: 10.536 | D15: 4.251 | E15: 56704 | F15: 3.306 | G15: 3402 | H15: 4268
A16: EU27 | B16: Denmark | C16: 5.555 | D16: 3.008 | E16: 21017 | F16: 2.229 | G16: 1250 | H16: 1528
A17: EU27 | B17: Estonia | C17: 1.332 | D17: 2.637 | E17: 4436 | F17: 2.162 | G17: 335 | H17: 315
A18: EU27 | B18: Finland | C18: 5.366 | D18: 2.167 | E18: 14910 | F18: 1.531 | G18: 805 | H18: 1098
A19: EU27 | B19: France | C19: 63.027 | D19: 3.832 | E19: 308667 | F19: 2.718 | G19: 15300 | H19: 20373
A20: EU27 | B20: Germany | C20: 80.895 | D20: 3.741 | E20: 384739 | F20: 2.646 | G20: 23692 | H20: 28156
A21: EU27 | B21: Greece | C21: 11.446 | D21: 5.401 | E21: 70352 | F21: 3.88 | G21: 4287 | H21: 5187
... A36: EU27 | B36: Sweden | C36: 9.39 | D36: 2.347 | E36: 26306 | F36: 1.535 | G36: 1614 | H36: 1934
A37: EU27 Total | C37: 440.529 | D37: 4.268 | E37: 2345461 | F37: 3.103 | G37: 138315 | H37: 168200
A38: NON EU27 | B38: Albania | C38: 2.941 | D38: 7.163 | E38: 21515 | F38: 5.448 | G38: 1027 | H38: 1625
A39: NON EU27 | B39: Armenia | C39: 2.877 | D39: 6.291 | E39: 21755 | F39: 5.686 | G39: 1280 | H39: 1511
A40: NON EU27 | B40: Azerbaijan | C40: 9.032 | D40: 5.334 | E40: 59804 | F40: 4.746 | G40: 1999 | H40: 4190
A41: NON EU27 | B41: Belarus | C41: 9.473 | D41: 5.365 | E41: 71762 | F41: 4.939 | G41: 5741 | H41: 5022
A42: NON EU27 | B42: Bosnia and Herzegovina | C42: 3.722 | D42: 9.509 | E42: 41753 | F42: 7.898 | G42: 2481 | H42: 3116
A43: NON EU27 | B43: Georgia | C43: 4.232 | D43: 7.396 | E43: 34283 | F43: 6.21 | G43: 2716 | H43: 2655
A44: NON EU27 | B44: Iceland | C44: 0.32 | D44: 2.618 | E44: 875 | F44: 1.756 | G44: 38 | H44: 62
A45: NON EU27 | B45: Kazakhstan | C45: 16.399 | D45: 14.34 | E45: 305554 | F45: 13.332 | G45: 15975 | H45: 20867
A46: NON EU27 | B46: Kosovo | C46: 1.827 | D46: 17.116 | E46: 13285 | F46: 13.522 | G46: 1052 | H46: 1072
A47: NON EU27 | B47: Kyrgyzstan | C47: 5.422 | D47: 6.318 | E47: 37584 | F47: 5.69 | G47: 1620 | H47: 2446
A48: NON EU27 | B48: North Macedonia | C48: 2.071 | D48: 9.449 | E48: 21860 | F48: 7.465 | G48: 1347 | H48: 1764
A49: NON EU27 | B49: Republic of Moldova | C49: 4.084 | D49: 7.298 | E49: 39032 | F49: 6.526 | G49: 2671 | H49: 2925
... A60: NON EU27 | B60: Uzbekistan | C60: 28.606 | D60: 7.686 | E60: 260072 | F60: 7.245 | G60: 7649 | H60: 16384
A61: NON EU27 Total | C61: 411.759 | D61: 6.358 | E61: 3235554 | F61: 5.507 | G61: 190662 | H61: 225067

Sheet yoll_Europe (14)
A2: Premature mortality due to PM2.5
A3: Scenario: B2/d/D/v5a
A4: Region:
A5: Year: 2040
A6: Unit: -,mln people, μg/m3, mln years,cases,cases
A7: UserID: StefanA
C9: Total Population (2010) | D9: Mean PM<sub>2.5</sub><br>concentration | E9: YOLL | F9: Months lost | G9: Premature deaths static | H9: Premature deaths
A10: EU27 | B10: Austria | C10: 8.41 | D10: 3.523 | E10: 36447 | F10: 2.423 | G10: 2026 | H10: 2624
A11: EU27 | B11: Belgium | C11: 10.939 | D11: 4.446 | E11: 59754 | F11: 3.144 | G11: 3510 | H11: 4186
A12: EU27 | B12: Bulgaria | C12: 7.405 | D12: 4.02 | E12: 37507 | F12: 3.246 | G12: 3353 | H12: 3053
A13: EU27 | B13: Croatia | C13: 4.328 | D13: 4.157 | E13: 21677 | F13: 3.357 | G13: 1606 | H13: 1654
A14: EU27 | B14: Cyprus | C14: 1.113 | D14: 5.273 | E14: 6323 | F14: 3.852 | G14: 286 | H14: 460
A15: EU27 | B15: Czech Republic | C15: 10.536 | D15: 4.244 | E15: 56600 | F15: 3.3 | G15: 3396 | H15: 4260
A16: EU27 | B16: Denmark | C16: 5.555 | D16: 2.995 | E16: 20927 | F16: 2.219 | G16: 1245 | H16: 1521
A17: EU27 | B17: Estonia | C17: 1.332 | D17: 2.633 | E17: 4428 | F17: 2.158 | G17: 335 | H17: 315
A18: EU27 | B18: Finland | C18: 5.366 | D18: 2.16 | E18: 14864 | F18: 1.526 | G18: 802 | H18: 1095
A19: EU27 | B19: France | C19: 63.027 | D19: 3.825 | E19: 308098 | F19: 2.713 | G19: 15272 | H19: 20336
A20: EU27 | B20: Germany | C20: 80.895 | D20: 3.723 | E20: 382831 | F20: 2.633 | G20: 23574 | H20: 28016
A21: EU27 | B21: Greece | C21: 11.446 | D21: 5.462 | E21: 71137 | F21: 3.923 | G21: 4334 | H21: 5245
... A36: EU27 | B36: Sweden | C36: 9.39 | D36: 2.341 | E36: 26242 | F36: 1.531 | G36: 1610 | H36: 1930
A37: EU27 Total | C37: 440.529 | D37: 4.263 | E37: 2342440 | F37: 3.099 | G37: 138141 | H37: 167984
A38: NON EU27 | B38: Albania | C38: 2.941 | D38: 7.26 | E38: 21808 | F38: 5.522 | G38: 1041 | H38: 1647
A39: NON EU27 | B39: Armenia | C39: 2.877 | D39: 6.382 | E39: 22070 | F39: 5.769 | G39: 1298 | H39: 1533
A40: NON EU27 | B40: Azerbaijan | C40: 9.032 | D40: 5.383 | E40: 60352 | F40: 4.79 | G40: 2017 | H40: 4228
A41: NON EU27 | B41: Belarus | C41: 9.473 | D41: 5.163 | E41: 69062 | F41: 4.754 | G41: 5525 | H41: 4833
A42: NON EU27 | B42: Bosnia and Herzegovina | C42: 3.722 | D42: 9.513 | E42: 41771 | F42: 7.901 | G42: 2482 | H42: 3118
A43: NON EU27 | B43: Georgia | C43: 4.232 | D43: 7.485 | E43: 34696 | F43: 6.285 | G43: 2749 | H43: 2687
A44: NON EU27 | B44: Iceland | C44: 0.32 | D44: 2.614 | E44: 874 | F44: 1.753 | G44: 38 | H44: 62
A45: NON EU27 | B45: Kazakhstan | C45: 16.399 | D45: 14.078 | E45: 299960 | F45: 13.088 | G45: 15682 | H45: 20485
A46: NON EU27 | B46: Kosovo | C46: 1.827 | D46: 17.156 | E46: 13316 | F46: 13.554 | G46: 1054 | H46: 1075
A47: NON EU27 | B47: Kyrgyzstan | C47: 5.422 | D47: 6.269 | E47: 37293 | F47: 5.646 | G47: 1607 | H47: 2427
A48: NON EU27 | B48: North Macedonia | C48: 2.071 | D48: 9.528 | E48: 22045 | F48: 7.528 | G48: 1358 | H48: 1779
A49: NON EU27 | B49: Republic of Moldova | C49: 4.084 | D49: 7.284 | E49: 38957 | F49: 6.513 | G49: 2666 | H49: 2920
... A60: NON EU27 | B60: Uzbekistan | C60: 28.606 | D60: 7.763 | E60: 262683 | F60: 7.318 | G60: 7726 | H60: 16548
A61: NON EU27 Total | C61: 411.759 | D61: 6.378 | E61: 3241191 | F61: 5.524 | G61: 190089 | H61: 225313

Sheet yoll_Europe (15)
A2: Premature mortality due to PM2.5
A3: Scenario: Base_v5a
A4: Region: | M4: Mort & Morb value borde vara högre i A1/s/D/v5a än i A1/s/G/v5a
A5: Year: 2040 | K5: Mort & Morb value borde vara högre i A1/d/D/v5a än i A1/d/G7v5a
A6: Unit: -,mln people, μg/m3, mln years,cases,cases
A7: UserID: StefanA | J7: TOTAL REGION
J8: Base_v5a | K8: A1/d/D/v5a | L8: A1/d/G/v5a | M8: A1/s/D/v5a | N8: A1/s/G/v5a | O8: A1r/d/D/v5a | P8: A1r/d/G/v5a | Q8: A1r/s/D/v5a | R8: A1r/s/G/v5a | S8: A2/d/D/v5a | T8: A3/d/D/v5a | U8: A2/s/D/v5a | V8: A3/s/D/v5a | W8: A4/s/D/v5a | X8: B1/d/D/v5a | Y8: B2/d/D/v5a
C9: Total Population (2010) | D9: Mean PM<sub>2.5</sub><br>concentration | E9: YOLL | F9: Months lost | G9: Premature deaths static | H9: Premature deaths | J9: Premature deaths | K9: Premature deaths | L9: Premature deaths | M9: Premature deaths | N9: Premature deaths | O9: Premature deaths | P9: Premature deaths | Q9: Premature deaths | R9: Premature deaths | S9: Premature deaths | T9: Premature deaths | U9: Premature deaths | V9: Premature deaths | W9: Premature deaths | X9: Premature deaths | Y9: Premature deaths
A10: EU27 | B10: Austria | C10: 8.41 | D10: 4.084 | E10: 42249 | F10: 2.809 | G10: 2349 | H10: 3041 | J10: =H37+H61 -> 524363 | K10: =yoll_Europe!H37+yoll_Europe!H61 -> 398669 | L10: ='yoll_Europe (1)'!H37+'yoll_Europe (1)'!H61 -> 473991 | M10: ='yoll_Europe (2)'!H37+'yoll_Europe (2)'!H61 -> 399302 | N10: ='yoll_Europe (3)'!H37+'yoll_Europe (3)'!H61 -> 472493 | O10: ='yoll_Europe (4)'!H37+'yoll_Europe (4)'!H61 -> 393300 | P10: ='yoll_Europe (5)'!H37+'yoll_Europe (5)'!H61 -> 393227 | Q10: ='yoll_Europe (6)'!H37+'yoll_Europe (6)'!H61 -> 468458 | R10: ='yoll_Europe (7)'!H37+'yoll_Europe (7)'!H61 -> 467016 | S10: ='yoll_Europe (8)'!H37+'yoll_Europe (8)'!H61 -> 352954 | T10: ='yoll_Europe (9)'!H37+'yoll_Europe (9)'!H61 -> 422384 | U10: ='yoll_Europe (10)'!H37+'yoll_Europe (10)'!H61 -> 352954 | V10: ='yoll_Europe (11)'!H37+'yoll_Europe (11)'!H61 -> 422384 | W10: ='yoll_Europe (12)'!H37+'yoll_Europe (12)'!H61 -> 375626 | X10: ='yoll_Europe (13)'!H37+'yoll_Europe (13)'!H61 -> 393267 | Y10: ='yoll_Europe (14)'!H37+'yoll_Europe (14)'!H61 -> 393297
A11: EU27 | B11: Belgium | C11: 10.939 | D11: 5.329 | E11: 71620 | F11: 3.768 | G11: 4207 | H11: 5018 | J11: reduction deaths | K11: =J10-K10 -> 125694 | L11: =$J10-L10 -> 50372 | M11: =$J10-M10 -> 125061 | N11: =$J10-N10 -> 51870 | O11: =$J10-O10 -> 131063 | P11: =$J10-P10 -> 131136 | Q11: =$J10-Q10 -> 55905 | R11: =$J10-R10 -> 57347 | S11: =$J10-S10 -> 171409 | ... Y11: =$J10-Y10 -> 131066
A12: EU27 | B12: Bulgaria | C12: 7.405 | D12: 5.568 | E12: 51942 | F12: 4.495 | G12: 4643 | H12: 4228
A13: EU27 | B13: Croatia | C13: 4.328 | D13: 5.186 | E13: 27040 | F13: 4.187 | G13: 2003 | H13: 2063
A14: EU27 | B14: Cyprus | C14: 1.113 | D14: 6.571 | E14: 7879 | F14: 4.8 | G14: 356 | H14: 573 | J14: Base_v5a | K14: A1r/d/D/v5a | L14: A1r/d/G/v5a
A15: EU27 | B15: Czech Republic | C15: 10.536 | D15: 5.009 | E15: 66807 | F15: 3.895 | G15: 4008 | H15: 5028 | J15: YOLL | K15: YOLL | L15: YOLL
A16: EU27 | B16: Denmark | C16: 5.555 | D16: 3.449 | E16: 24100 | F16: 2.556 | G16: 1434 | H16: 1752 | J16: =E37+E61 -> 7466045 | K16: =yoll_Europe!E37+yoll_Europe!E61 -> 5676131 | L16: ='yoll_Europe (1)'!E37+'yoll_Europe (1)'!E61 -> 6744609
A17: EU27 | B17: Estonia | C17: 1.332 | D17: 3.04 | E17: 5113 | F17: 2.492 | G17: 387 | H17: 363 | J17: reduction YOLL | K17: =J16-K16 -> 1789914 | L17: =J16-L16 -> 721436
A18: EU27 | B18: Finland | C18: 5.366 | D18: 2.452 | E18: 16873 | F18: 1.733 | G18: 910 | H18: 1243
A19: EU27 | B19: France | C19: 63.027 | D19: 4.439 | E19: 357601 | F19: 3.149 | G19: 17726 | H19: 23603
A20: EU27 | B20: Germany | C20: 80.895 | D20: 4.326 | E20: 444910 | F20: 3.06 | G20: 27397 | H20: 32559
A21: EU27 | B21: Greece | C21: 11.446 | D21: 6.495 | E21: 84596 | F21: 4.666 | G21: 5155 | H21: 6237
A22: EU27 | B22: Hungary | C22: 9.928 | D22: 5.876 | E22: 78423 | F22: 5.04 | G22: 5820 | H22: 5826
A23: EU27 | B23: Ireland | C23: 4.627 | D23: 2.066 | E23: 9682 | F23: 1.393 | G23: 427 | H23: 701
A24: EU27 | B24: Italy | C24: 59.73 | D24: 6.454 | E24: 482698 | F24: 4.367 | G24: 27989 | H24: 34860
A25: EU27 | B25: Latvia | C25: 2.119 | D25: 3.813 | E25: 10016 | F25: 3.279 | G25: 910 | H25: 744
A26: EU27 | B26: Lithuania | C26: 3.124 | D26: 3.768 | E26: 15208 | F26: 3.316 | G26: 1263 | H26: 1087
A27: EU27 | B27: Luxembourg | C27: 0.508 | D27: 3.755 | E27: 2300 | F27: 2.449 | G27: 111 | H27: 157
A28: EU27 | B28: Malta | C28: 0.416 | D28: 7.763 | E28: 3951 | F28: 5.689 | G28: 194 | H28: 302
A29: EU27 | B29: Netherlands | C29: 16.683 | D29: 5.554 | E29: 109926 | F29: 3.848 | G29: 5662 | H29: 8183
... A36: EU27 | B36: Sweden | C36: 9.39 | D36: 2.594 | E36: 29068 | F36: 1.696 | G36: 1783 | H36: 2138
A37: EU27 Total | C37: 440.529 | D37: 4.97 | E37: 2732754 | F37: 3.625 | G37: 161767 | H37: 196111
A38: NON EU27 | B38: Albania | C38: 2.941 | D38: 10.936 | E38: 32852 | F38: 8.318 | G38: 1568 | H38: 2482
A39: NON EU27 | B39: Armenia | C39: 2.877 | D39: 12.917 | E39: 44668 | F39: 11.675 | G39: 2627 | H39: 3102
A40: NON EU27 | B40: Azerbaijan | C40: 9.032 | D40: 8.585 | E40: 96248 | F40: 7.639 | G40: 3217 | H40: 6743
A41: NON EU27 | B41: Belarus | C41: 9.473 | D41: 7.12 | E41: 95241 | F41: 6.556 | G41: 7620 | H41: 6665
A42: NON EU27 | B42: Bosnia and Herzegovina | C42: 3.722 | D42: 12.411 | E42: 54497 | F42: 10.309 | G42: 3238 | H42: 4068
A43: NON EU27 | B43: Georgia | C43: 4.232 | D43: 9.019 | E43: 41807 | F43: 7.573 | G43: 3312 | H43: 3238
A44: NON EU27 | B44: Iceland | C44: 0.32 | D44: 3.088 | E44: 1032 | F44: 2.072 | G44: 45 | H44: 73
A45: NON EU27 | B45: Kazakhstan | C45: 16.399 | D45: 17.939 | E45: 382232 | F45: 16.678 | G45: 19983 | H45: 26103
A46: NON EU27 | B46: Kosovo | C46: 1.827 | D46: 20.032 | E46: 15549 | F46: 15.826 | G46: 1231 | H46: 1255
A47: NON EU27 | B47: Kyrgyzstan | C47: 5.422 | D47: 11.969 | E47: 71201 | F47: 10.78 | G47: 3068 | H47: 4634
...
