Workbook
Name CI_Range: #REF!
Name CI_range_2: #REF!
Name CL: #REF!
Name Cl_metr_2: #REF!
Name Cl_metric: #REF!
Name CM: #REF!
Name DK: #REF!
Name Q: #REF!
Name Range: #REF!

Sheet Temp_decay
A1: Source | B1: Type | C1: Ref_SC | D1: Discount rate | E1: SC-Range | F1: Scenario year | G1: Pollutant | H1: Control NPV (USD, $) | I1: Control NPV (Euro) | J1: Net Present Value (NPV) | K1: Unit value | L1: Phys-Parameter | M1: P-0 | N1: P-1 | O1: P-2 | P1: P-3 | Q1: P-4 | R1: P-5 | S1: P-6 | T1: P-7 | U1: P-8 | V1: P-9 | W1: P-10 | X1: P-11 | Y1: P-12 | Z1: P-13 | AA1: P-14 | AB1: P-15 | AC1: P-16 | AD1: P-17 | AE1: P-18 | AF1: P-19 | AG1: P-20 | AH1: P-21 | AI1: P-22 | AJ1: P-23 | AK1: P-24 | AL1: P-25 | AM1: P-26 | AN1: P-27 | AO1: P-28 | AP1: P-29 | AQ1: P-30 | AR1: P-31 | AS1: P-32 | AT1: P-33 | AU1: P-34 | AV1: P-35 | AW1: P-36 | AX1: P-37 | AY1: P-38 | AZ1: P-39 | BA1: P-40 | BB1: P-41 | BC1: P-42 | BD1: P-43 | BE1: P-44 | BF1: P-45 | BG1: P-46 | BH1: P-47 | BI1: P-48 | BJ1: P-49 | BK1: P-50 | BL1: P-51 | BM1: P-52 | BN1: P-53 | BO1: P-54 | BP1: P-55 | BQ1: P-56 | BR1: P-57 | BS1: P-58 | BT1: P-59 | BU1: P-60 | BV1: P-61 | BW1: P-62 | BX1: P-63 | BY1: P-64 | BZ1: P-65 | CA1: P-66 | CB1: P-67 | CC1: P-68 | CD1: P-69 | CE1: P-70 | CF1: P-71 | CG1: P-72 | CH1: P-73 | CI1: P-74 | CJ1: P-75 | CK1: P-76 | CL1: P-77 | CM1: P-78 | CN1: P-79 | CO1: P-80 | CP1: P-81 | CQ1: P-82 | CR1: P-83 | CS1: P-84 | CT1: P-85 | CU1: P-86 | CV1: P-87 | CW1: P-88 | CX1: P-89 | CY1: P-90 | CZ1: P-91 | DA1: P-92 | DB1: P-93 | DC1: P-94 | DD1: P-95 | DE1: P-96 | DF1: P-97 | DG1: P-98 | DH1: P-99 | DI1: P-100 | DJ1: P-101 | DK1: P-102 | DL1: P-103 | DM1: P-104 | DN1: P-105 | DO1: P-106 | DP1: P-107 | DQ1: P-108 | DR1: P-109 | DS1: P-110 | DT1: P-111 | DU1: P-112 | DV1: P-113 | DW1: P-114 | DX1: P-115 | DY1: P-116 | DZ1: P-117 | EA1: P-118 | EB1: P-119 | EC1: P-120 | ED1: P-121 | EE1: P-122 | EF1: P-123 | EG1: P-124 | EH1: P-125 | EI1: P-126 | EJ1: P-127 | EK1: P-128 | EL1: P-129 | EM1: P-130 | EN1: P-131 | EO1: P-132 | EP1: P-133 | EQ1: P-134 | ER1: P-135 | ES1: P-136 | ET1: P-137 | EU1: P-138 | EV1: P-139 | EW1: P-140 | EX1: P-141 | EY1: P-142 | EZ1: P-143 | FA1: P-144 | FB1: P-145 | FC1: P-146 | FD1: P-147 | FE1: P-148 | FF1: P-149 | FG1: P-150 | FH1: P-151 | FI1: P-152 | FJ1: P-153 | FK1: P-154 | FL1: P-155 | FM1: P-156 | FN1: P-157 | FO1: P-158 | FP1: P-159 | FQ1: P-160 | FR1: P-161 | FS1: P-162 | FT1: P-163 | FU1: P-164 | FV1: P-165 | FW1: P-166 | FX1: P-167 | FY1: P-168 | FZ1: P-169 | GA1: P-170 | GB1: P-171 | GC1: P-172 | GD1: P-173 | GE1: P-174 | GF1: P-175 | GG1: P-176 | GH1: P-177 | GI1: P-178 | GJ1: P-179 | GK1: P-180 | GL1: P-181 | GM1: P-182 | GN1: P-183 | GO1: P-184 | GP1: P-185 | GQ1: P-186 | GR1: P-187 | GS1: P-188 | GT1: P-189 | GU1: P-190 | GV1: P-191 | GW1: P-192 | GX1: P-193 | GY1: P-194 | GZ1: P-195 | HA1: P-196 | HB1: P-197 | HC1: P-198 | HD1: P-199 | HE1: P-200 | HF1: P-201 | HG1: P-202 | HH1: P-203 | HI1: P-204 | HJ1: P-205 | HK1: P-206 | HL1: P-207 | HM1: P-208 | HN1: P-209 | HO1: P-210 | HP1: P-211 | HQ1: P-212 | HR1: P-213 | HS1: P-214 | HT1: P-215 | HU1: P-216 | HV1: P-217 | HW1: P-218 | HX1: P-219 | HY1: P-220 | HZ1: P-221 | IA1: P-222 | IB1: P-223 | IC1: P-224 | ID1: P-225 | IE1: P-226 | IF1: P-227 | IG1: P-228 | IH1: P-229 | II1: P-230 | IJ1: P-231 | IK1: P-232 | IL1: P-233 | IM1: P-234 | IN1: P-235 | IO1: P-236 | IP1: P-237 | IQ1: P-238 | IR1: P-239 | IS1: P-240 | IT1: P-241 | IU1: P-242 | IV1: P-243 | IW1: P-244 | IX1: P-245 | IY1: P-246 | IZ1: P-247 | JA1: P-248 | JB1: P-249 | JC1: P-250 | JD1: P-251 | JE1: P-252 | JF1: P-253 | JG1: P-254 | JH1: P-255 | JI1: P-256 | JJ1: P-257 | JK1: P-258 | JL1: P-259 | JM1: P-260 | JN1: P-261 | JO1: P-262 | JP1: P-263 | JQ1: P-264 | JR1: P-265 | JS1: P-266 | JT1: P-267 | JU1: P-268 | JV1: P-269 | JW1: P-270 | JX1: P-271 | JY1: P-272 | JZ1: P-273 | KA1: P-274 | KB1: P-275 | KC1: P-276 | KD1: P-277 | KE1: P-278 | KF1: P-279 | KG1: P-280 | KH1: P-281 | KI1: P-282 | KJ1: P-283 | KK1: P-284 | KL1: P-285 | KM1: P-286 | KN1: P-287 | KO1: P-288 | KP1: P-289 | KQ1: P-290 | KR1: P-291 | KS1: P-292 | KT1: P-293 | KU1: P-294 | KV1: P-295 | KW1: P-296 | KX1: P-297 | KY1: P-298 | KZ1: P-299 | LA1: P-300 | LB1: P-301 | LC1: P-302 | LD1: P-303 | LE1: P-304 | LF1: P-305 | LG1: P-306 | LH1: P-307 | LI1: P-308 | LJ1: P-309 | LK1: P-310 | LL1: P-311 | LM1: P-312 | LN1: P-313 | LO1: P-314 | LP1: P-315 | LQ1: P-316 | LR1: P-317 | LS1: P-318 | LT1: P-319 | LU1: P-320 | LV1: P-321 | LW1: P-322 | LX1: P-323 | LY1: P-324 | LZ1: P-325 | MA1: P-326 | MB1: P-327 | MC1: P-328 | MD1: P-329 | ME1: P-330 | MF1: P-331 | MG1: P-332 | MH1: P-333 | MI1: P-334 | MJ1: P-335 | MK1: P-336 | ML1: P-337 | MM1: P-338 | MN1: P-339 | MO1: P-340 | MP1: P-341 | MQ1: P-342 | MR1: P-343 | MS1: P-344 | MT1: P-345 | MU1: P-346 | MV1: P-347 | MW1: P-348 | MX1: P-349 | MY1: P-350 | MZ1: P-351 | NA1: P-352 | NB1: P-353 | NC1: P-354 | ND1: P-355 | NE1: P-356 | NF1: P-357 | NG1: P-358 | NH1: P-359 | NI1: P-360 | NJ1: P-361 | NK1: P-362 | NL1: P-363 | NM1: P-364 | NN1: P-365 | NO1: P-366 | NP1: P-367 | NQ1: P-368 | NR1: P-369 | NS1: P-370 | NT1: P-371 | NU1: P-372 | NV1: P-373 | NW1: P-374 | NX1: P-375 | NY1: P-376 | NZ1: P-377 | OA1: P-378 | OB1: P-379 | OC1: P-380 | OD1: P-381 | OE1: P-382 | OF1: P-383 | OG1: P-384 | OH1: P-385 | OI1: P-386 | OJ1: P-387 | OK1: P-388 | OL1: P-389 | OM1: P-390 | ON1: P-391 | OO1: P-392 | OP1: P-393 | OQ1: P-394 | OR1: P-395 | OS1: P-396 | OT1: P-397 | OU1: P-398 | OV1: P-399 | OW1: P-400
A2: SC_SLCP_2024-11-28.xlsx | B2: Physical | L2: time after pulse | M2: 0 | N2: 1 | O2: 2 | P2: 3 | Q2: 4 | R2: 5 | S2: 6 | T2: 7 | U2: 8 | V2: 9 | W2: 10 | X2: 11 | Y2: 12 | Z2: 13 | AA2: 14 | AB2: 15 | AC2: 16 | AD2: 17 | AE2: 18 | AF2: 19 | AG2: 20 | AH2: 21 | AI2: 22 | AJ2: 23 | AK2: 24 | AL2: 25 | AM2: 26 | AN2: 27 | AO2: 28 | AP2: 29 | AQ2: 30 | AR2: 31 | AS2: 32 | AT2: 33 | AU2: 34 | AV2: 35 | AW2: 36 | AX2: 37 | AY2: 38 | AZ2: 39 | BA2: 40 | BB2: 41 | BC2: 42 | BD2: 43 | BE2: 44 | BF2: 45 | BG2: 46 | BH2: 47 | BI2: 48 | BJ2: 49 | BK2: 50 | BL2: 51 | BM2: 52 | BN2: 53 | BO2: 54 | BP2: 55 | BQ2: 56 | BR2: 57 | BS2: 58 | BT2: 59 | BU2: 60 | BV2: 61 | BW2: 62 | BX2: 63 | BY2: 64 | BZ2: 65 | CA2: 66 | CB2: 67 | CC2: 68 | CD2: 69 | CE2: 70 | CF2: 71 | CG2: 72 | CH2: 73 | CI2: 74 | CJ2: 75 | CK2: 76 | CL2: 77 | CM2: 78 | CN2: 79 | CO2: 80 | CP2: 81 | CQ2: 82 | CR2: 83 | CS2: 84 | CT2: 85 | CU2: 86 | CV2: 87 | CW2: 88 | CX2: 89 | CY2: 90 | CZ2: 91 | DA2: 92 | DB2: 93 | DC2: 94 | DD2: 95 | DE2: 96 | DF2: 97 | DG2: 98 | DH2: 99 | DI2: 100 | DJ2: 101 | DK2: 102 | DL2: 103 | DM2: 104 | DN2: 105 | DO2: 106 | DP2: 107 | DQ2: 108 | DR2: 109 | DS2: 110 | DT2: 111 | DU2: 112 | DV2: 113 | DW2: 114 | DX2: 115 | DY2: 116 | DZ2: 117 | EA2: 118 | EB2: 119 | EC2: 120 | ED2: 121 | EE2: 122 | EF2: 123 | EG2: 124 | EH2: 125 | EI2: 126 | EJ2: 127 | EK2: 128 | EL2: 129 | EM2: 130 | EN2: 131 | EO2: 132 | EP2: 133 | EQ2: 134 | ER2: 135 | ES2: 136 | ET2: 137 | EU2: 138 | EV2: 139 | EW2: 140 | EX2: 141 | EY2: 142 | EZ2: 143 | FA2: 144 | FB2: 145 | FC2: 146 | FD2: 147 | FE2: 148 | FF2: 149 | FG2: 150 | FH2: 151 | FI2: 152 | FJ2: 153 | FK2: 154 | FL2: 155 | FM2: 156 | FN2: 157 | FO2: 158 | FP2: 159 | FQ2: 160 | FR2: 161 | FS2: 162 | FT2: 163 | FU2: 164 | FV2: 165 | FW2: 166 | FX2: 167 | FY2: 168 | FZ2: 169 | GA2: 170 | GB2: 171 | GC2: 172 | GD2: 173 | GE2: 174 | GF2: 175 | GG2: 176 | GH2: 177 | GI2: 178 | GJ2: 179 | GK2: 180 | GL2: 181 | GM2: 182 | GN2: 183 | GO2: 184 | GP2: 185 | GQ2: 186 | GR2: 187 | GS2: 188 | GT2: 189 | GU2: 190 | GV2: 191 | GW2: 192 | GX2: 193 | GY2: 194 | GZ2: 195 | HA2: 196 | HB2: 197 | HC2: 198 | HD2: 199 | HE2: 200 | HF2: 201 | HG2: 202 | HH2: 203 | HI2: 204 | HJ2: 205 | HK2: 206 | HL2: 207 | HM2: 208 | HN2: 209 | HO2: 210 | HP2: 211 | HQ2: 212 | HR2: 213 | HS2: 214 | HT2: 215 | HU2: 216 | HV2: 217 | HW2: 218 | HX2: 219 | HY2: 220 | HZ2: 221 | IA2: 222 | IB2: 223 | IC2: 224 | ID2: 225 | IE2: 226 | IF2: 227 | IG2: 228 | IH2: 229 | II2: 230 | IJ2: 231 | IK2: 232 | IL2: 233 | IM2: 234 | IN2: 235 | IO2: 236 | IP2: 237 | IQ2: 238 | IR2: 239 | IS2: 240 | IT2: 241 | IU2: 242 | IV2: 243 | IW2: 244 | IX2: 245 | IY2: 246 | IZ2: 247 | JA2: 248 | JB2: 249 | JC2: 250 | JD2: 251 | JE2: 252 | JF2: 253 | JG2: 254 | JH2: 255 | JI2: 256 | JJ2: 257 | JK2: 258 | JL2: 259 | JM2: 260 | JN2: 261 | JO2: 262 | JP2: 263 | JQ2: 264 | JR2: 265 | JS2: 266 | JT2: 267 | JU2: 268 | JV2: 269 | JW2: 270 | JX2: 271 | JY2: 272 | JZ2: 273 | KA2: 274 | KB2: 275 | KC2: 276 | KD2: 277 | KE2: 278 | KF2: 279 | KG2: 280 | KH2: 281 | KI2: 282 | KJ2: 283 | KK2: 284 | KL2: 285 | KM2: 286 | KN2: 287 | KO2: 288 | KP2: 289 | KQ2: 290 | KR2: 291 | KS2: 292 | KT2: 293 | KU2: 294 | KV2: 295 | KW2: 296 | KX2: 297 | KY2: 298 | KZ2: 299 | LA2: 300 | LB2: 301 | LC2: 302 | LD2: 303 | LE2: 304 | LF2: 305 | LG2: 306 | LH2: 307 | LI2: 308 | LJ2: 309 | LK2: 310 | LL2: 311 | LM2: 312 | LN2: 313 | LO2: 314 | LP2: 315 | LQ2: 316 | LR2: 317 | LS2: 318 | LT2: 319 | LU2: 320 | LV2: 321 | LW2: 322 | LX2: 323 | LY2: 324 | LZ2: 325 | MA2: 326 | MB2: 327 | MC2: 328 | MD2: 329 | ME2: 330 | MF2: 331 | MG2: 332 | MH2: 333 | MI2: 334 | MJ2: 335 | MK2: 336 | ML2: 337 | MM2: 338 | MN2: 339 | MO2: 340 | MP2: 341 | MQ2: 342 | MR2: 343 | MS2: 344 | MT2: 345 | MU2: 346 | MV2: 347 | MW2: 348 | MX2: 349 | MY2: 350 | MZ2: 351 | NA2: 352 | NB2: 353 | NC2: 354 | ND2: 355 | NE2: 356 | NF2: 357 | NG2: 358 | NH2: 359 | NI2: 360 | NJ2: 361 | NK2: 362 | NL2: 363 | NM2: 364 | NN2: 365 | NO2: 366 | NP2: 367 | NQ2: 368 | NR2: 369 | NS2: 370 | NT2: 371 | NU2: 372 | NV2: 373 | NW2: 374 | NX2: 375 | NY2: 376 | NZ2: 377 | OA2: 378 | OB2: 379 | OC2: 380 | OD2: 381 | OE2: 382 | OF2: 383 | OG2: 384 | OH2: 385 | OI2: 386 | OJ2: 387 | OK2: 388 | OL2: 389 | OM2: 390 | ON2: 391 | OO2: 392 | OP2: 393 | OQ2: 394 | OR2: 395 | OS2: 396 | OT2: 397 | OU2: 398 | OV2: 399 | OW2: 400
A3: SC_SLCP_2024-11-28.xlsx | B3: Physical | L3: a: 0.01 year | M3: 0 | N3: 0.9617 | O3: 0.92 | P3: 0.88 | Q3: 0.84 | R3: 0.8 | S3: 0.77 | T3: 0.74 | U3: 0.72 | V3: 0.7 | W3: 0.68 | X3: 0.67372218 | Y3: 0.66693974 | Z3: 0.65966912 | AA3: 0.65192784 | AB3: 0.65 | AC3: 0.63688424 | AD3: 0.62323861 | AE3: 0.60910882 | AF3: 0.59454144 | AG3: 0.58 | AH3: 0.5764872 | AI3: 0.57282993 | AJ3: 0.56903123 | AK3: 0.56509423 | AL3: 0.56 | AM3: 0.55580382 | AN3: 0.55147952 | AO3: 0.5470306 | AP3: 0.54246062 | AQ3: 0.5391 | AR3: 0.53740316 | AS3: 0.53565719 | AT3: 0.5338626 | AU3: 0.53201991 | AV3: 0.5309 | AW3: 0.52924588 | AX3: 0.52755118 | AY3: 0.52581633 | AZ3: 0.52404176 | BA3: 0.5215 | BB3: 0.52067911 | BC3: 0.51983955 | BD3: 0.51898139 | BE3: 0.51810474 | BF3: 0.5165 | BG3: 0.51519732 | BH3: 0.51386971 | BI3: 0.51251739 | BJ3: 0.51114056 | BK3: 0.5102 | BL3: 0.50912943 | BM3: 0.50804019 | BN3: 0.5069324 | BO3: 0.50580619 | BP3: 0.50466169 | BQ3: 0.50349905 | BR3: 0.5023184 | BS3: 0.50111987 | BT3: 0.49990362 | BU3: 0.4989 | BV3: 0.4980709 | BW3: 0.49722962 | BX3: 0.49637622 | BY3: 0.49551078 | BZ3: 0.49463337 | CA3: 0.49374404 | CB3: 0.49284287 | CC3: 0.49192994 | CD3: 0.4910053 | CE3: 0.4904 | CF3: 0.48951061 | CG3: 0.48861033 | CH3: 0.48769925 | CI3: 0.48677741 | CJ3: 0.4858449 | CK3: 0.48490178 | CL3: 0.48394811 | CM3: 0.48298397 | CN3: 0.48200943 | CO3: 0.4814 | CP3: 0.4806943 | CQ3: 0.47998095 | CR3: 0.47925997 | CS3: 0.47853141 | CT3: 0.47779531 | CU3: 0.47705169 | CV3: 0.47630061 | CW3: 0.4755421 | CX3: 0.47477619 | CY3: 0.4734 | CZ3: 0.47250046 | DA3: 0.47159277 | DB3: 0.47067699 | DC3: 0.46975317 | DD3: 0.46882136 | DE3: 0.46788162 | DF3: 0.46693401 | DG3: 0.46597857 | DH3: 0.46501537 | DI3: 0.4644 | DJ3: 0.463885 | DK3: 0.46337 | DL3: 0.462855 | DM3: 0.46234 | DN3: 0.461825 | DO3: 0.46131 | DP3: 0.460795 | DQ3: 0.46028 | DR3: 0.459765 | DS3: 0.45925 | DT3: 0.458735 | DU3: 0.45822 | DV3: 0.457705 | DW3: 0.45719 | DX3: 0.456675 | DY3: 0.45616 | DZ3: 0.455645 | EA3: 0.45513 | EB3: 0.454615 | EC3: 0.4541 | ED3: 0.453585 | EE3: 0.45307 | EF3: 0.452555 | EG3: 0.45204 | EH3: 0.451525 | EI3: 0.45101 | EJ3: 0.450495 | EK3: 0.44998 | EL3: 0.449465 | EM3: 0.44895 | EN3: 0.448435 | EO3: 0.44792 | EP3: 0.447405 | EQ3: 0.44689 | ER3: 0.446375 | ES3: 0.44586 | ET3: 0.445345 | EU3: 0.44483 | EV3: 0.444315 | EW3: 0.4438 | EX3: 0.443285 | EY3: 0.44277 | EZ3: 0.442255 | FA3: 0.44174 | FB3: 0.441225 | FC3: 0.44071 | FD3: 0.440195 | FE3: 0.43968 | FF3: 0.439165 | FG3: 0.43865 | FH3: 0.438135 | FI3: 0.43762 | FJ3: 0.437105 | FK3: 0.43659 | FL3: 0.436075 | FM3: 0.43556 | FN3: 0.435045 | FO3: 0.43453 | FP3: 0.434015 | FQ3: 0.4335 | FR3: 0.432985 | FS3: 0.43247 | FT3: 0.431955 | FU3: 0.43144 | FV3: 0.430925 | FW3: 0.43041 | FX3: 0.429895 | FY3: 0.42938 | FZ3: 0.428865 | GA3: 0.42835 | GB3: 0.427835 | GC3: 0.42732 | GD3: 0.426805 | GE3: 0.42629 | GF3: 0.425775 | GG3: 0.42526 | GH3: 0.424745 | GI3: 0.42423 | GJ3: 0.423715 | GK3: 0.4232 | GL3: 0.422685 | GM3: 0.42217 | GN3: 0.421655 | GO3: 0.42114 | GP3: 0.420625 | GQ3: 0.42011 | GR3: 0.419595 | GS3: 0.41908 | GT3: 0.418565 | GU3: 0.41805 | GV3: 0.417535 | GW3: 0.41702 | GX3: 0.416505 | GY3: 0.41599 | GZ3: 0.415475 | HA3: 0.41496 | HB3: 0.414445 | HC3: 0.41393 | HD3: 0.413415 | HE3: 0.4129 | HF3: 0.412386 | HG3: 0.411872 | HH3: 0.411358 | HI3: 0.410844 | HJ3: 0.41033 | HK3: 0.409816 | HL3: 0.409302 | HM3: 0.408788 | HN3: 0.408274 | HO3: 0.40776 | HP3: 0.407246 | HQ3: 0.406732 | HR3: 0.406218 | HS3: 0.405704 | HT3: 0.40519 | HU3: 0.404676 | HV3: 0.404162 | HW3: 0.403648 | HX3: 0.403134 | HY3: 0.40262 | HZ3: 0.402106 | IA3: 0.401592 | IB3: 0.401078 | IC3: 0.400564 | ID3: 0.40005 | IE3: 0.399536 | IF3: 0.399022 | IG3: 0.398508 | IH3: 0.397994 | II3: 0.39748 | IJ3: 0.396966 | IK3: 0.396452 | IL3: 0.395938 | IM3: 0.395424 | IN3: 0.39491 | IO3: 0.394396 | IP3: 0.393882 | IQ3: 0.393368 | IR3: 0.392854 | IS3: 0.39234 | IT3: 0.391826 | IU3: 0.391312 | IV3: 0.390798 | IW3: 0.390284 | IX3: 0.38977 | IY3: 0.389256 | IZ3: 0.388742 | JA3: 0.388228 | JB3: 0.387714 | JC3: 0.3872 | JD3: 0.386686 | JE3: 0.386172 | JF3: 0.385658 | JG3: 0.385144 | JH3: 0.38463 | JI3: 0.384116 | JJ3: 0.383602 | JK3: 0.383088 | JL3: 0.382574 | JM3: 0.38206 | JN3: 0.381546 | JO3: 0.381032 | JP3: 0.380518 | JQ3: 0.380004 | JR3: 0.37949 | JS3: 0.378976 | JT3: 0.378462 | JU3: 0.377948 | JV3: 0.377434 | JW3: 0.37692 | JX3: 0.376406 | JY3: 0.375892 | JZ3: 0.375378 | KA3: 0.374864 | KB3: 0.37435 | KC3: 0.373836 | KD3: 0.373322 | KE3: 0.372808 | KF3: 0.372294 | KG3: 0.37178 | KH3: 0.371266 | KI3: 0.370752 | KJ3: 0.370238 | KK3: 0.369724 | KL3: 0.36921 | KM3: 0.368696 | KN3: 0.368182 | KO3: 0.367668 | KP3: 0.367154 | KQ3: 0.36664 | KR3: 0.366126 | KS3: 0.365612 | KT3: 0.365098 | KU3: 0.364584 | KV3: 0.36407 | KW3: 0.363556 | KX3: 0.363042 | KY3: 0.362528 | KZ3: 0.362014 | LA3: 0.3615 | LB3: 0.360985 | LC3: 0.36047 | LD3: 0.359955 | LE3: 0.35944 | LF3: 0.358925 | LG3: 0.35841 | LH3: 0.357895 | LI3: 0.35738 | LJ3: 0.356865 | LK3: 0.35635 | LL3: 0.355835 | LM3: 0.35532 | LN3: 0.354805 | LO3: 0.35429 | LP3: 0.353775 | LQ3: 0.35326 | LR3: 0.352745 | LS3: 0.35223 | LT3: 0.351715 | LU3: 0.3512 | LV3: 0.350685 | LW3: 0.35017 | LX3: 0.349655 | LY3: 0.34914 | LZ3: 0.348625 | MA3: 0.34811 | MB3: 0.347595 | MC3: 0.34708 | MD3: 0.346565 | ME3: 0.34605 | MF3: 0.345535 | MG3: 0.34502 | MH3: 0.344505 | MI3: 0.34399 | MJ3: 0.343475 | MK3: 0.34296 | ML3: 0.342445 | MM3: 0.34193 | MN3: 0.341415 | MO3: 0.3409 | MP3: 0.340385 | MQ3: 0.33987 | MR3: 0.339355 | MS3: 0.33884 | MT3: 0.338325 | MU3: 0.33781 | MV3: 0.337295 | MW3: 0.33678 | MX3: 0.336265 | MY3: 0.33575 | MZ3: 0.335235 | NA3: 0.33472 | NB3: 0.334205 | NC3: 0.33369 | ND3: 0.333175 | NE3: 0.33266 | NF3: 0.332145 | NG3: 0.33163 | NH3: 0.331115 | NI3: 0.3306 | NJ3: 0.330085 | NK3: 0.32957 | NL3: 0.329055 | NM3: 0.32854 | NN3: 0.328025 | NO3: 0.32751 | NP3: 0.326995 | NQ3: 0.32648 | NR3: 0.325965 | NS3: 0.32545 | NT3: 0.324935 | NU3: 0.32442 | NV3: 0.323905 | NW3: 0.32339 | NX3: 0.322875 | NY3: 0.32236 | NZ3: 0.321845 | OA3: 0.32133 | OB3: 0.320815 | OC3: 0.3203 | OD3: 0.319785 | OE3: 0.31927 | OF3: 0.318755 | OG3: 0.31824 | OH3: 0.317725 | OI3: 0.31721 | OJ3: 0.316695 | OK3: 0.31618 | OL3: 0.315665 | OM3: 0.31515 | ON3: 0.314635 | OO3: 0.31412 | OP3: 0.313605 | OQ3: 0.31309 | OR3: 0.312575 | OS3: 0.31206 | OT3: 0.311545 | OU3: 0.31103 | OV3: 0.310515 | OW3: 0.31
A4: SC_SLCP_2024-11-28.xlsx | B4: Physical | L4: b: 0.01 year | M4: 0 | N4: 0.0144 | O4: 0.0303 | P4: 0.0377 | Q4: 0.0416 | R4: 0.0445 | S4: 0.0452 | T4: 0.0443 | U4: 0.0448 | V4: 0.0425 | W4: 0.0405 | X4: 0.0404 | Y4: 0.0403 | Z4: 0.0402 | AA4: 0.0401 | AB4: 0.04 | AC4: 0.0356 | AD4: 0.0312 | AE4: 0.0268 | AF4: 0.0224 | AG4: 0.018 | AH4: 0.01672 | AI4: 0.01544 | AJ4: 0.01416 | AK4: 0.01288 | AL4: 0.0116 | AM4: 0.01088 | AN4: 0.01016 | AO4: 0.00944 | AP4: 0.00872 | AQ4: 0.008 | AR4: 0.00766 | AS4: 0.00732 | AT4: 0.00698 | AU4: 0.00664 | AV4: 0.0063 | AW4: 0.00582 | AX4: 0.00534 | AY4: 0.00486 | AZ4: 0.00438 | BA4: 0.0039 | BB4: 0.0039 | BC4: 0.0039 | BD4: 0.0039 | BE4: 0.0039 | BF4: 0.0039 | BG4: 0.00374 | BH4: 0.00358 | BI4: 0.00342 | BJ4: 0.00326 | BK4: 0.0031 | BL4: 0.00302 | BM4: 0.00294 | BN4: 0.00286 | BO4: 0.00278 | BP4: 0.0027 | BQ4: 0.00262 | BR4: 0.00254 | BS4: 0.00246 | BT4: 0.00238 | BU4: 0.0023 | BV4: 0.00222 | BW4: 0.00214 | BX4: 0.00206 | BY4: 0.00198 | BZ4: 0.0019 | CA4: 0.00182 | CB4: 0.00174 | CC4: 0.00166 | CD4: 0.00158 | CE4: 0.0015 | CF4: 0.00156 | CG4: 0.00162 | CH4: 0.00168 | CI4: 0.00174 | CJ4: 0.0018 | CK4: 0.00186 | CL4: 0.00192 | CM4: 0.00198 | CN4: 0.00204 | CO4: 0.0021 | CP4: 0.00211 | CQ4: 0.00212 | CR4: 0.00213 | CS4: 0.00214 | CT4: 0.00215 | CU4: 0.00216 | CV4: 0.00217 | CW4: 0.00218 | CX4: 0.00219 | CY4: 0.0022 | CZ4: 0.0022 | DA4: 0.0022 | DB4: 0.0022 | DC4: 0.0022 | DD4: 0.0022 | DE4: 0.0022 | DF4: 0.0022 | DG4: 0.0022 | DH4: 0.0022 | DI4: 0.0022 | DJ4: 0.002194 | DK4: 0.002188 | DL4: 0.002182 | DM4: 0.002176 | DN4: 0.00217 | DO4: 0.002164 | DP4: 0.002158 | DQ4: 0.002152 | DR4: 0.002146 | DS4: 0.00214 | DT4: 0.002134 | DU4: 0.002128 | DV4: 0.002122 | DW4: 0.002116 | DX4: 0.00211 | DY4: 0.002104 | DZ4: 0.002098 | EA4: 0.002092 | EB4: 0.002086 | EC4: 0.00208 | ED4: 0.002074 | EE4: 0.002068 | EF4: 0.002062 | EG4: 0.002056 | EH4: 0.00205 | EI4: 0.002044 | EJ4: 0.002038 | EK4: 0.002032 | EL4: 0.002026 | EM4: 0.00202 | EN4: 0.002014 | EO4: 0.002008 | EP4: 0.002002 | EQ4: 0.001996 | ER4: 0.00199 | ES4: 0.001984 | ET4: 0.001978 | EU4: 0.001972 | EV4: 0.001966 | EW4: 0.00196 | EX4: 0.001954 | EY4: 0.001948 | EZ4: 0.001942 | FA4: 0.001936 | FB4: 0.00193 | FC4: 0.001924 | FD4: 0.001918 | FE4: 0.001912 | FF4: 0.001906 | FG4: 0.0019 | FH4: 0.001894 | FI4: 0.001888 | FJ4: 0.001882 | FK4: 0.001876 | FL4: 0.00187 | FM4: 0.001864 | FN4: 0.001858 | FO4: 0.001852 | FP4: 0.001846 | FQ4: 0.00184 | FR4: 0.001834 | FS4: 0.001828 | FT4: 0.001822 | FU4: 0.001816 | FV4: 0.00181 | FW4: 0.001804 | FX4: 0.001798 | FY4: 0.001792 | FZ4: 0.001786 | GA4: 0.00178 | GB4: 0.001774 | GC4: 0.001768 | GD4: 0.001762 | GE4: 0.001756 | GF4: 0.00175 | GG4: 0.001744 | GH4: 0.001738 | GI4: 0.001732 | GJ4: 0.001726 | GK4: 0.00172 | GL4: 0.001714 | GM4: 0.001708 | GN4: 0.001702 | GO4: 0.001696 | GP4: 0.00169 | GQ4: 0.001684 | GR4: 0.001678 | GS4: 0.001672 | GT4: 0.001666 | GU4: 0.00166 | GV4: 0.001654 | GW4: 0.001648 | GX4: 0.001642 | GY4: 0.001636 | GZ4: 0.00163 | HA4: 0.001624 | HB4: 0.001618 | HC4: 0.001612 | HD4: 0.001606 | HE4: 0.0016 | HF4: 0.001593 | HG4: 0.001586 | HH4: 0.001579 | HI4: 0.001572 | HJ4: 0.001565 | HK4: 0.001558 | HL4: 0.001551 | HM4: 0.001544 | HN4: 0.001537 | HO4: 0.00153 | HP4: 0.001523 | HQ4: 0.001516 | HR4: 0.001509 | HS4: 0.001502 | HT4: 0.001495 | HU4: 0.001488 | HV4: 0.001481 | HW4: 0.001474 | HX4: 0.001467 | HY4: 0.00146 | HZ4: 0.001453 | IA4: 0.001446 | IB4: 0.001439 | IC4: 0.001432 | ID4: 0.001425 | IE4: 0.001418 | IF4: 0.001411 | IG4: 0.001404 | IH4: 0.001397 | II4: 0.00139 | IJ4: 0.001383 | IK4: 0.001376 | IL4: 0.001369 | IM4: 0.001362 | IN4: 0.001355 | IO4: 0.001348 | IP4: 0.001341 | IQ4: 0.001334 | IR4: 0.001327 | IS4: 0.00132 | IT4: 0.001313 | IU4: 0.001306 | IV4: 0.001299 | IW4: 0.001292 | IX4: 0.001285 | IY4: 0.001278 | IZ4: 0.001271 | JA4: 0.001264 | JB4: 0.001257 | JC4: 0.00125 | JD4: 0.001243 | JE4: 0.001236 | JF4: 0.001229 | JG4: 0.001222 | JH4: 0.001215 | JI4: 0.001208 | JJ4: 0.001201 | JK4: 0.001194 | JL4: 0.001187 | JM4: 0.00118 | JN4: 0.001173 | JO4: 0.001166 | JP4: 0.001159 | JQ4: 0.001152 | JR4: 0.001145 | JS4: 0.001138 | JT4: 0.001131 | JU4: 0.001124 | JV4: 0.001117 | JW4: 0.00111 | JX4: 0.001103 | JY4: 0.001096 | JZ4: 0.001089 | KA4: 0.001082 | KB4: 0.001075 | KC4: 0.001068 | KD4: 0.001061 | KE4: 0.001054 | KF4: 0.001047 | KG4: 0.00104 | KH4: 0.001033 | KI4: 0.001026 | KJ4: 0.001019 | KK4: 0.001012 | KL4: 0.001005 | KM4: 0.000998 | KN4: 0.000991 | KO4: 0.000984 | KP4: 0.000977 | KQ4: 0.00097 | KR4: 0.000963 | KS4: 0.000956 | KT4: 0.000949 | KU4: 0.000942 | KV4: 0.000935 | KW4: 0.000928 | KX4: 0.000921 | KY4: 0.000914 | KZ4: 0.000907 | LA4: 0.0009 | LB4: 0.000891 | LC4: 0.000882 | LD4: 0.000873 | LE4: 0.000864 | LF4: 0.000855 | LG4: 0.000846 | LH4: 0.000837 | LI4: 0.000828 | LJ4: 0.000819 | LK4: 0.00081 | LL4: 0.000801 | LM4: 0.000792 | LN4: 0.000783 | LO4: 0.000774 | LP4: 0.000765 | LQ4: 0.000756 | LR4: 0.000747 | LS4: 0.000738 | LT4: 0.000729 | LU4: 0.00072 | LV4: 0.000711 | LW4: 0.000702 | LX4: 0.000693 | LY4: 0.000684 | LZ4: 0.000675 | MA4: 0.000666 | MB4: 0.000657 | MC4: 0.000648 | MD4: 0.000639 | ME4: 0.00063 | MF4: 0.000621 | MG4: 0.000612 | MH4: 0.000603 | MI4: 0.000594 | MJ4: 0.000585 | MK4: 0.000576 | ML4: 0.000567 | MM4: 0.000558 | MN4: 0.000549 | MO4: 0.00054 | MP4: 0.000531 | MQ4: 0.000522 | MR4: 0.000513 | MS4: 0.000504 | MT4: 0.000495 | MU4: 0.000486 | MV4: 0.000477 | MW4: 0.000468 | MX4: 0.000459 | MY4: 0.00045 | MZ4: 0.000441 | NA4: 0.000432 | NB4: 0.000423 | NC4: 0.000414 | ND4: 0.000405 | NE4: 0.000396 | NF4: 0.000387 | NG4: 0.000378 | NH4: 0.000369 | NI4: 0.00036 | NJ4: 0.000351 | NK4: 0.000342 | NL4: 0.000333 | NM4: 0.000324 | NN4: 0.000315 | NO4: 0.000306 | NP4: 0.000297 | NQ4: 0.000288 | NR4: 0.000279 | NS4: 0.00027 | NT4: 0.000261 | NU4: 0.000252 | NV4: 0.000243 | NW4: 0.000234 | NX4: 0.000225 | NY4: 0.000216 | NZ4: 0.000207 | OA4: 0.000198 | OB4: 0.000189 | OC4: 0.00018 | OD4: 0.000171 | OE4: 0.000162 | OF4: 0.000153 | OG4: 0.000144 | OH4: 0.000135 | OI4: 0.000126 | OJ4: 0.000117 | OK4: 0.000108 | OL4: 9.9e-05 | OM4: 9e-05 | ON4: 8.1e-05 | OO4: 7.2e-05 | OP4: 6.3e-05 | OQ4: 5.4e-05 | OR4: 4.5e-05 | OS4: 3.6e-05 | OT4: 2.7e-05 | OU4: 1.8e-05 | OV4: 9e-06 | OW4: 0
A5: SC_SLCP_2024-11-28.xlsx | B5: Physical | L5: a: 10 year | M5: 0 | N5: 0.9617 | O5: 0.915 | P5: 0.88 | Q5: 0.857 | R5: 0.82 | S5: 0.795 | T5: 0.78 | U5: 0.76 | V5: 0.74 | W5: 0.72 | X5: 0.7036147 | Y5: 0.68616481 | Z5: 0.66774878 | AA5: 0.64846852 | AB5: 0.64 | AC5: 0.63334615 | AD5: 0.62635221 | AE5: 0.61903103 | AF5: 0.61139594 | AG5: 0.607 | AH5: 0.60179273 | AI5: 0.5963854 | AJ5: 0.59078423 | AK5: 0.5849956 | AL5: 0.579 | AM5: 0.57466145 | AN5: 0.57019043 | AO5: 0.56559056 | AP5: 0.56086553 | AQ5: 0.559 | AR5: 0.55562474 | AS5: 0.55216198 | AT5: 0.5486136 | AU5: 0.54498155 | AV5: 0.54 | AW5: 0.53831753 | AX5: 0.53659378 | AY5: 0.53482919 | AZ5: 0.5330242 | BA5: 0.53 | BB5: 0.52916573 | BC5: 0.52831248 | BD5: 0.52744034 | BE5: 0.5265494 | BF5: 0.5165 | BG5: 0.51519732 | BH5: 0.51386971 | BI5: 0.51251739 | BJ5: 0.51114056 | BK5: 0.5102 | BL5: 0.50912943 | BM5: 0.50804019 | BN5: 0.5069324 | BO5: 0.50580619 | BP5: 0.50466169 | BQ5: 0.50349905 | BR5: 0.5023184 | BS5: 0.50111987 | BT5: 0.49990362 | BU5: 0.4989 | BV5: 0.4980709 | BW5: 0.49722962 | BX5: 0.49637622 | BY5: 0.49551078 | BZ5: 0.49463337 | CA5: 0.49374404 | CB5: 0.49284287 | CC5: 0.49192994 | CD5: 0.4910053 | CE5: 0.4904 | CF5: 0.48951061 | CG5: 0.48861033 | CH5: 0.48769925 | CI5: 0.48677741 | CJ5: 0.4858449 | CK5: 0.48490178 | CL5: 0.48394811 | CM5: 0.48298397 | CN5: 0.48200943 | CO5: 0.4814 | CP5: 0.4806943 | CQ5: 0.47998095 | CR5: 0.47925997 | CS5: 0.47853141 | CT5: 0.47779531 | CU5: 0.47705169 | CV5: 0.47630061 | CW5: 0.4755421 | CX5: 0.47477619 | CY5: 0.4734 | CZ5: 0.47250046 | DA5: 0.47159277 | DB5: 0.47067699 | DC5: 0.46975317 | DD5: 0.46882136 | DE5: 0.46788162 | DF5: 0.46693401 | DG5: 0.46597857 | DH5: 0.46501537 | DI5: 0.4644 | DJ5: 0.463885 | DK5: 0.46337 | DL5: 0.462855 | DM5: 0.46234 | DN5: 0.461825 | DO5: 0.46131 | DP5: 0.460795 | DQ5: 0.46028 | DR5: 0.459765 | DS5: 0.45925 | DT5: 0.458735 | DU5: 0.45822 | DV5: 0.457705 | DW5: 0.45719 | DX5: 0.456675 | DY5: 0.45616 | DZ5: 0.455645 | EA5: 0.45513 | EB5: 0.454615 | EC5: 0.4541 | ED5: 0.453585 | EE5: 0.45307 | EF5: 0.452555 | EG5: 0.45204 | EH5: 0.451525 | EI5: 0.45101 | EJ5: 0.450495 | EK5: 0.44998 | EL5: 0.449465 | EM5: 0.44895 | EN5: 0.448435 | EO5: 0.44792 | EP5: 0.447405 | EQ5: 0.44689 | ER5: 0.446375 | ES5: 0.44586 | ET5: 0.445345 | EU5: 0.44483 | EV5: 0.444315 | EW5: 0.4438 | EX5: 0.443285 | EY5: 0.44277 | EZ5: 0.442255 | FA5: 0.44174 | FB5: 0.441225 | FC5: 0.44071 | FD5: 0.440195 | FE5: 0.43968 | FF5: 0.439165 | FG5: 0.43865 | FH5: 0.438135 | FI5: 0.43762 | FJ5: 0.437105 | FK5: 0.43659 | FL5: 0.436075 | FM5: 0.43556 | FN5: 0.435045 | FO5: 0.43453 | FP5: 0.434015 | FQ5: 0.4335 | FR5: 0.432985 | FS5: 0.43247 | FT5: 0.431955 | FU5: 0.43144 | FV5: 0.430925 | FW5: 0.43041 | FX5: 0.429895 | FY5: 0.42938 | FZ5: 0.428865 | GA5: 0.42835 | GB5: 0.427835 | GC5: 0.42732 | GD5: 0.426805 | GE5: 0.42629 | GF5: 0.425775 | GG5: 0.42526 | GH5: 0.424745 | GI5: 0.42423 | GJ5: 0.423715 | GK5: 0.4232 | GL5: 0.422685 | GM5: 0.42217 | GN5: 0.421655 | GO5: 0.42114 | GP5: 0.420625 | GQ5: 0.42011 | GR5: 0.419595 | GS5: 0.41908 | GT5: 0.418565 | GU5: 0.41805 | GV5: 0.417535 | GW5: 0.41702 | GX5: 0.416505 | GY5: 0.41599 | GZ5: 0.415475 | HA5: 0.41496 | HB5: 0.414445 | HC5: 0.41393 | HD5: 0.413415 | HE5: 0.4129 | HF5: 0.412386 | HG5: 0.411872 | HH5: 0.411358 | HI5: 0.410844 | HJ5: 0.41033 | HK5: 0.409816 | HL5: 0.409302 | HM5: 0.408788 | HN5: 0.408274 | HO5: 0.40776 | HP5: 0.407246 | HQ5: 0.406732 | HR5: 0.406218 | HS5: 0.405704 | HT5: 0.40519 | HU5: 0.404676 | HV5: 0.404162 | HW5: 0.403648 | HX5: 0.403134 | HY5: 0.40262 | HZ5: 0.402106 | IA5: 0.401592 | IB5: 0.401078 | IC5: 0.400564 | ID5: 0.40005 | IE5: 0.399536 | IF5: 0.399022 | IG5: 0.398508 | IH5: 0.397994 | II5: 0.39748 | IJ5: 0.396966 | IK5: 0.396452 | IL5: 0.395938 | IM5: 0.395424 | IN5: 0.39491 | IO5: 0.394396 | IP5: 0.393882 | IQ5: 0.393368 | IR5: 0.392854 | IS5: 0.39234 | IT5: 0.391826 | IU5: 0.391312 | IV5: 0.390798 | IW5: 0.390284 | IX5: 0.38977 | IY5: 0.389256 | IZ5: 0.388742 | JA5: 0.388228 | JB5: 0.387714 | JC5: 0.3872 | JD5: 0.386686 | JE5: 0.386172 | JF5: 0.385658 | JG5: 0.385144 | JH5: 0.38463 | JI5: 0.384116 | JJ5: 0.383602 | JK5: 0.383088 | JL5: 0.382574 | JM5: 0.38206 | JN5: 0.381546 | JO5: 0.381032 | JP5: 0.380518 | JQ5: 0.380004 | JR5: 0.37949 | JS5: 0.378976 | JT5: 0.378462 | JU5: 0.377948 | JV5: 0.377434 | JW5: 0.37692 | JX5: 0.376406 | JY5: 0.375892 | JZ5: 0.375378 | KA5: 0.374864 | KB5: 0.37435 | KC5: 0.373836 | KD5: 0.373322 | KE5: 0.372808 | KF5: 0.372294 | KG5: 0.37178 | KH5: 0.371266 | KI5: 0.370752 | KJ5: 0.370238 | KK5: 0.369724 | KL5: 0.36921 | KM5: 0.368696 | KN5: 0.368182 | KO5: 0.367668 | KP5: 0.367154 | KQ5: 0.36664 | KR5: 0.366126 | KS5: 0.365612 | KT5: 0.365098 | KU5: 0.364584 | KV5: 0.36407 | KW5: 0.363556 | KX5: 0.363042 | KY5: 0.362528 | KZ5: 0.362014 | LA5: 0.3615 | LB5: 0.360985 | LC5: 0.36047 | LD5: 0.359955 | LE5: 0.35944 | LF5: 0.358925 | LG5: 0.35841 | LH5: 0.357895 | LI5: 0.35738 | LJ5: 0.356865 | LK5: 0.35635 | LL5: 0.355835 | LM5: 0.35532 | LN5: 0.354805 | LO5: 0.35429 | LP5: 0.353775 | LQ5: 0.35326 | LR5: 0.352745 | LS5: 0.35223 | LT5: 0.351715 | LU5: 0.3512 | LV5: 0.350685 | LW5: 0.35017 | LX5: 0.349655 | LY5: 0.34914 | LZ5: 0.348625 | MA5: 0.34811 | MB5: 0.347595 | MC5: 0.34708 | MD5: 0.346565 | ME5: 0.34605 | MF5: 0.345535 | MG5: 0.34502 | MH5: 0.344505 | MI5: 0.34399 | MJ5: 0.343475 | MK5: 0.34296 | ML5: 0.342445 | MM5: 0.34193 | MN5: 0.341415 | MO5: 0.3409 | MP5: 0.340385 | MQ5: 0.33987 | MR5: 0.339355 | MS5: 0.33884 | MT5: 0.338325 | MU5: 0.33781 | MV5: 0.337295 | MW5: 0.33678 | MX5: 0.336265 | MY5: 0.33575 | MZ5: 0.335235 | NA5: 0.33472 | NB5: 0.334205 | NC5: 0.33369 | ND5: 0.333175 | NE5: 0.33266 | NF5: 0.332145 | NG5: 0.33163 | NH5: 0.331115 | NI5: 0.3306 | NJ5: 0.330085 | NK5: 0.32957 | NL5: 0.329055 | NM5: 0.32854 | NN5: 0.328025 | NO5: 0.32751 | NP5: 0.326995 | NQ5: 0.32648 | NR5: 0.325965 | NS5: 0.32545 | NT5: 0.324935 | NU5: 0.32442 | NV5: 0.323905 | NW5: 0.32339 | NX5: 0.322875 | NY5: 0.32236 | NZ5: 0.321845 | OA5: 0.32133 | OB5: 0.320815 | OC5: 0.3203 | OD5: 0.319785 | OE5: 0.31927 | OF5: 0.318755 | OG5: 0.31824 | OH5: 0.317725 | OI5: 0.31721 | OJ5: 0.316695 | OK5: 0.31618 | OL5: 0.315665 | OM5: 0.31515 | ON5: 0.314635 | OO5: 0.31412 | OP5: 0.313605 | OQ5: 0.31309 | OR5: 0.312575 | OS5: 0.31206 | OT5: 0.311545 | OU5: 0.31103 | OV5: 0.310515 | OW5: 0.31
A6: SC_SLCP_2024-11-28.xlsx | B6: Physical | L6: b: 10 year | M6: 0 | N6: 0.0144 | O6: 0.0303 | P6: 0.0377 | Q6: 0.0416 | R6: 0.0445 | S6: 0.0452 | T6: 0.0443 | U6: 0.0448 | V6: 0.0425 | W6: 0.0405 | X6: 0.0404 | Y6: 0.0403 | Z6: 0.0402 | AA6: 0.0401 | AB6: 0.04 | AC6: 0.0356 | AD6: 0.0312 | AE6: 0.0268 | AF6: 0.0224 | AG6: 0.018 | AH6: 0.01672 | AI6: 0.01544 | AJ6: 0.01416 | AK6: 0.01288 | AL6: 0.0116 | AM6: 0.01088 | AN6: 0.01016 | AO6: 0.00944 | AP6: 0.00872 | AQ6: 0.008 | AR6: 0.00766 | AS6: 0.00732 | AT6: 0.00698 | AU6: 0.00664 | AV6: 0.0063 | AW6: 0.00582 | AX6: 0.00534 | AY6: 0.00486 | AZ6: 0.00438 | BA6: 0.0039 | BB6: 0.0039 | BC6: 0.0039 | BD6: 0.0039 | BE6: 0.0039 | BF6: 0.0039 | BG6: 0.00374 | BH6: 0.00358 | BI6: 0.00342 | BJ6: 0.00326 | BK6: 0.0031 | BL6: 0.00302 | BM6: 0.00294 | BN6: 0.00286 | BO6: 0.00278 | BP6: 0.0027 | BQ6: 0.00262 | BR6: 0.00254 | BS6: 0.00246 | BT6: 0.00238 | BU6: 0.0023 | BV6: 0.00222 | BW6: 0.00214 | BX6: 0.00206 | BY6: 0.00198 | BZ6: 0.0019 | CA6: 0.00182 | CB6: 0.00174 | CC6: 0.00166 | CD6: 0.00158 | CE6: 0.0015 | CF6: 0.00156 | CG6: 0.00162 | CH6: 0.00168 | CI6: 0.00174 | CJ6: 0.0018 | CK6: 0.00186 | CL6: 0.00192 | CM6: 0.00198 | CN6: 0.00204 | CO6: 0.0021 | CP6: 0.00211 | CQ6: 0.00212 | CR6: 0.00213 | CS6: 0.00214 | CT6: 0.00215 | CU6: 0.00216 | CV6: 0.00217 | CW6: 0.00218 | CX6: 0.00219 | CY6: 0.0022 | CZ6: 0.0022 | DA6: 0.0022 | DB6: 0.0022 | DC6: 0.0022 | DD6: 0.0022 | DE6: 0.0022 | DF6: 0.0022 | DG6: 0.0022 | DH6: 0.0022 | DI6: 0.0022 | DJ6: 0.002194 | DK6: 0.002188 | DL6: 0.002182 | DM6: 0.002176 | DN6: 0.00217 | DO6: 0.002164 | DP6: 0.002158 | DQ6: 0.002152 | DR6: 0.002146 | DS6: 0.00214 | DT6: 0.002134 | DU6: 0.002128 | DV6: 0.002122 | DW6: 0.002116 | DX6: 0.00211 | DY6: 0.002104 | DZ6: 0.002098 | EA6: 0.002092 | EB6: 0.002086 | EC6: 0.00208 | ED6: 0.002074 | EE6: 0.002068 | EF6: 0.002062 | EG6: 0.002056 | EH6: 0.00205 | EI6: 0.002044 | EJ6: 0.002038 | EK6: 0.002032 | EL6: 0.002026 | EM6: 0.00202 | EN6: 0.002014 | EO6: 0.002008 | EP6: 0.002002 | EQ6: 0.001996 | ER6: 0.00199 | ES6: 0.001984 | ET6: 0.001978 | EU6: 0.001972 | EV6: 0.001966 | EW6: 0.00196 | EX6: 0.001954 | EY6: 0.001948 | EZ6: 0.001942 | FA6: 0.001936 | FB6: 0.00193 | FC6: 0.001924 | FD6: 0.001918 | FE6: 0.001912 | FF6: 0.001906 | FG6: 0.0019 | FH6: 0.001894 | FI6: 0.001888 | FJ6: 0.001882 | FK6: 0.001876 | FL6: 0.00187 | FM6: 0.001864 | FN6: 0.001858 | FO6: 0.001852 | FP6: 0.001846 | FQ6: 0.00184 | FR6: 0.001834 | FS6: 0.001828 | FT6: 0.001822 | FU6: 0.001816 | FV6: 0.00181 | FW6: 0.001804 | FX6: 0.001798 | FY6: 0.001792 | FZ6: 0.001786 | GA6: 0.00178 | GB6: 0.001774 | GC6: 0.001768 | GD6: 0.001762 | GE6: 0.001756 | GF6: 0.00175 | GG6: 0.001744 | GH6: 0.001738 | GI6: 0.001732 | GJ6: 0.001726 | GK6: 0.00172 | GL6: 0.001714 | GM6: 0.001708 | GN6: 0.001702 | GO6: 0.001696 | GP6: 0.00169 | GQ6: 0.001684 | GR6: 0.001678 | GS6: 0.001672 | GT6: 0.001666 | GU6: 0.00166 | GV6: 0.001654 | GW6: 0.001648 | GX6: 0.001642 | GY6: 0.001636 | GZ6: 0.00163 | HA6: 0.001624 | HB6: 0.001618 | HC6: 0.001612 | HD6: 0.001606 | HE6: 0.0016 | HF6: 0.001593 | HG6: 0.001586 | HH6: 0.001579 | HI6: 0.001572 | HJ6: 0.001565 | HK6: 0.001558 | HL6: 0.001551 | HM6: 0.001544 | HN6: 0.001537 | HO6: 0.00153 | HP6: 0.001523 | HQ6: 0.001516 | HR6: 0.001509 | HS6: 0.001502 | HT6: 0.001495 | HU6: 0.001488 | HV6: 0.001481 | HW6: 0.001474 | HX6: 0.001467 | HY6: 0.00146 | HZ6: 0.001453 | IA6: 0.001446 | IB6: 0.001439 | IC6: 0.001432 | ID6: 0.001425 | IE6: 0.001418 | IF6: 0.001411 | IG6: 0.001404 | IH6: 0.001397 | II6: 0.00139 | IJ6: 0.001383 | IK6: 0.001376 | IL6: 0.001369 | IM6: 0.001362 | IN6: 0.001355 | IO6: 0.001348 | IP6: 0.001341 | IQ6: 0.001334 | IR6: 0.001327 | IS6: 0.00132 | IT6: 0.001313 | IU6: 0.001306 | IV6: 0.001299 | IW6: 0.001292 | IX6: 0.001285 | IY6: 0.001278 | IZ6: 0.001271 | JA6: 0.001264 | JB6: 0.001257 | JC6: 0.00125 | JD6: 0.001243 | JE6: 0.001236 | JF6: 0.001229 | JG6: 0.001222 | JH6: 0.001215 | JI6: 0.001208 | JJ6: 0.001201 | JK6: 0.001194 | JL6: 0.001187 | JM6: 0.00118 | JN6: 0.001173 | JO6: 0.001166 | JP6: 0.001159 | JQ6: 0.001152 | JR6: 0.001145 | JS6: 0.001138 | JT6: 0.001131 | JU6: 0.001124 | JV6: 0.001117 | JW6: 0.00111 | JX6: 0.001103 | JY6: 0.001096 | JZ6: 0.001089 | KA6: 0.001082 | KB6: 0.001075 | KC6: 0.001068 | KD6: 0.001061 | KE6: 0.001054 | KF6: 0.001047 | KG6: 0.00104 | KH6: 0.001033 | KI6: 0.001026 | KJ6: 0.001019 | KK6: 0.001012 | KL6: 0.001005 | KM6: 0.000998 | KN6: 0.000991 | KO6: 0.000984 | KP6: 0.000977 | KQ6: 0.00097 | KR6: 0.000963 | KS6: 0.000956 | KT6: 0.000949 | KU6: 0.000942 | KV6: 0.000935 | KW6: 0.000928 | KX6: 0.000921 | KY6: 0.000914 | KZ6: 0.000907 | LA6: 0.0009 | LB6: 0.000891 | LC6: 0.000882 | LD6: 0.000873 | LE6: 0.000864 | LF6: 0.000855 | LG6: 0.000846 | LH6: 0.000837 | LI6: 0.000828 | LJ6: 0.000819 | LK6: 0.00081 | LL6: 0.000801 | LM6: 0.000792 | LN6: 0.000783 | LO6: 0.000774 | LP6: 0.000765 | LQ6: 0.000756 | LR6: 0.000747 | LS6: 0.000738 | LT6: 0.000729 | LU6: 0.00072 | LV6: 0.000711 | LW6: 0.000702 | LX6: 0.000693 | LY6: 0.000684 | LZ6: 0.000675 | MA6: 0.000666 | MB6: 0.000657 | MC6: 0.000648 | MD6: 0.000639 | ME6: 0.00063 | MF6: 0.000621 | MG6: 0.000612 | MH6: 0.000603 | MI6: 0.000594 | MJ6: 0.000585 | MK6: 0.000576 | ML6: 0.000567 | MM6: 0.000558 | MN6: 0.000549 | MO6: 0.00054 | MP6: 0.000531 | MQ6: 0.000522 | MR6: 0.000513 | MS6: 0.000504 | MT6: 0.000495 | MU6: 0.000486 | MV6: 0.000477 | MW6: 0.000468 | MX6: 0.000459 | MY6: 0.00045 | MZ6: 0.000441 | NA6: 0.000432 | NB6: 0.000423 | NC6: 0.000414 | ND6: 0.000405 | NE6: 0.000396 | NF6: 0.000387 | NG6: 0.000378 | NH6: 0.000369 | NI6: 0.00036 | NJ6: 0.000351 | NK6: 0.000342 | NL6: 0.000333 | NM6: 0.000324 | NN6: 0.000315 | NO6: 0.000306 | NP6: 0.000297 | NQ6: 0.000288 | NR6: 0.000279 | NS6: 0.00027 | NT6: 0.000261 | NU6: 0.000252 | NV6: 0.000243 | NW6: 0.000234 | NX6: 0.000225 | NY6: 0.000216 | NZ6: 0.000207 | OA6: 0.000198 | OB6: 0.000189 | OC6: 0.00018 | OD6: 0.000171 | OE6: 0.000162 | OF6: 0.000153 | OG6: 0.000144 | OH6: 0.000135 | OI6: 0.000126 | OJ6: 0.000117 | OK6: 0.000108 | OL6: 9.9e-05 | OM6: 9e-05 | ON6: 8.1e-05 | OO6: 7.2e-05 | OP6: 6.3e-05 | OQ6: 5.4e-05 | OR6: 4.5e-05 | OS6: 3.6e-05 | OT6: 2.7e-05 | OU6: 1.8e-05 | OV6: 9e-06 | OW6: 0
A7: SC_SLCP_2024-11-28.xlsx | B7: Physical | L7: lt-PMres | M7: =10/3.65/100 -> 0.02739726 | N7: =M7 -> 0.02739726 | O7: =N7 -> 0.02739726 | P7: =O7 -> 0.02739726 | Q7: =P7 -> 0.02739726 | R7: =Q7 -> 0.02739726 | S7: =R7 -> 0.02739726 | T7: =S7 -> 0.02739726 | U7: =T7 -> 0.02739726 | ... OW7: =OV7 -> 0.02739726
A8: SC_SLCP_2024-11-28.xlsx | B8: Physical | L8: lt-BC | M8: =10/3.65/100 -> 0.02739726 | N8: =M8 -> 0.02739726 | O8: =N8 -> 0.02739726 | P8: =O8 -> 0.02739726 | Q8: =P8 -> 0.02739726 | R8: =Q8 -> 0.02739726 | S8: =R8 -> 0.02739726 | T8: =S8 -> 0.02739726 | U8: =T8 -> 0.02739726 | ... OW8: =OV8 -> 0.02739726
A9: SC_SLCP_2024-11-28.xlsx | B9: Physical | L9: lt-OC | M9: =10/3.65/100 -> 0.02739726 | N9: =M9 -> 0.02739726 | O9: =N9 -> 0.02739726 | P9: =O9 -> 0.02739726 | Q9: =P9 -> 0.02739726 | R9: =Q9 -> 0.02739726 | S9: =R9 -> 0.02739726 | T9: =S9 -> 0.02739726 | U9: =T9 -> 0.02739726 | ... OW9: =OV9 -> 0.02739726
A10: SC_SLCP_2024-11-28.xlsx | B10: Physical | L10: lt-NMVOC | M10: 0.01 | N10: =M10 -> 0.01 | O10: =N10 -> 0.01 | P10: =O10 -> 0.01 | Q10: =P10 -> 0.01 | R10: =Q10 -> 0.01 | S10: =R10 -> 0.01 | T10: =S10 -> 0.01 | U10: =T10 -> 0.01 | ... OW10: =OV10 -> 0.01
A11: SC_SLCP_2024-11-28.xlsx | B11: Physical | L11: lt-CH4 | M11: 11.8 | N11: =M11 -> 11.8 | O11: =N11 -> 11.8 | P11: =O11 -> 11.8 | Q11: =P11 -> 11.8 | R11: =Q11 -> 11.8 | S11: =R11 -> 11.8 | T11: =S11 -> 11.8 | U11: =T11 -> 11.8 | ... OW11: =OV11 -> 11.8
A12: SC_SLCP_2024-11-28.xlsx | B12: Physical | L12: lt-NOx | M12: 0.01 | N12: =M12 -> 0.01 | O12: =N12 -> 0.01 | P12: =O12 -> 0.01 | Q12: =P12 -> 0.01 | R12: =Q12 -> 0.01 | S12: =R12 -> 0.01 | T12: =S12 -> 0.01 | U12: =T12 -> 0.01 | ... OW12: =OV12 -> 0.01
A13: SC_SLCP_2024-11-28.xlsx | B13: Physical | L13: lt-SO2 | M13: =10/3.65/100 -> 0.02739726 | N13: =M13 -> 0.02739726 | O13: =N13 -> 0.02739726 | P13: =O13 -> 0.02739726 | Q13: =P13 -> 0.02739726 | R13: =Q13 -> 0.02739726 | S13: =R13 -> 0.02739726 | T13: =S13 -> 0.02739726 | U13: =T13 -> 0.02739726 | ... OW13: =OV13 -> 0.02739726
A14: SC_SLCP_2024-11-28.xlsx | B14: Physical | L14: lt-NH3 | M14: 0.01 | N14: =M14 -> 0.01 | O14: =N14 -> 0.01 | P14: =O14 -> 0.01 | Q14: =P14 -> 0.01 | R14: =Q14 -> 0.01 | S14: =R14 -> 0.01 | T14: =S14 -> 0.01 | U14: =T14 -> 0.01 | ... OW14: =OV14 -> 0.01
A15: SC_SLCP_2024-11-28.xlsx | B15: Physical | L15: decay-PMres | M15: 1 | N15: 0.9 | O15: =O$3*O7^O$4 -> 0.82499317 | P15: =P$3*P7^P$4 -> 0.76839447 | Q15: =Q$3*Q7^Q$4 -> 0.7232491 | R15: =R$3*R7^R$4 -> 0.68166023 | S15: =S$3*S7^S$4 -> 0.65444791 | T15: =T$3*T7^T$4 -> 0.63098952 | U15: =U$3*U7^U$4 -> 0.61283248 | V15: =V$3*V7^V$4 -> 0.60075943 | ... OW15: =OW$3*OW7^OW$4 -> 0.31
A16: SC_SLCP_2024-11-28.xlsx | B16: Physical | L16: decay-BC | M16: 1 | N16: 0.9 | O16: =O$3*O8^O$4 -> 0.82499317 | P16: =P$3*P8^P$4 -> 0.76839447 | Q16: =Q$3*Q8^Q$4 -> 0.7232491 | R16: =R$3*R8^R$4 -> 0.68166023 | S16: =S$3*S8^S$4 -> 0.65444791 | T16: =T$3*T8^T$4 -> 0.63098952 | U16: =U$3*U8^U$4 -> 0.61283248 | V16: =V$3*V8^V$4 -> 0.60075943 | ... OW16: =OW$3*OW8^OW$4 -> 0.31
A17: SC_SLCP_2024-11-28.xlsx | B17: Physical | L17: decay-OC | M17: 1 | N17: 0.9 | O17: =O$3*O9^O$4 -> 0.82499317 | P17: =P$3*P9^P$4 -> 0.76839447 | Q17: =Q$3*Q9^Q$4 -> 0.7232491 | R17: =R$3*R9^R$4 -> 0.68166023 | S17: =S$3*S9^S$4 -> 0.65444791 | T17: =T$3*T9^T$4 -> 0.63098952 | U17: =U$3*U9^U$4 -> 0.61283248 | V17: =V$3*V9^V$4 -> 0.60075943 | ... OW17: =OW$3*OW9^OW$4 -> 0.31
A18: SC_SLCP_2024-11-28.xlsx | B18: Physical | L18: decay-NMVOC | M18: 1 | N18: 0.9 | O18: =O$3*O10^O$4 -> 0.80018025 | P18: =P$3*P10^P$4 -> 0.73974608 | Q18: =Q$3*Q10^Q$4 -> 0.69355241 | R18: =R$3*R10^R$4 -> 0.65176343 | S18: =S$3*S10^S$4 -> 0.62530331 | T18: =T$3*T10^T$4 -> 0.6034367 | U18: =U$3*U10^U$4 -> 0.58577724 | V18: =V$3*V10^V$4 -> 0.57556985 | ... OW18: =OW$3*OW10^OW$4 -> 0.31
A19: SC_SLCP_2024-11-28.xlsx | B19: Physical | L19: decay-CH4 | M19: 1 | N19: 0.99 | O19: =O$5*O11^O$6 -> 0.98605041 | P19: =P$5*P11^P$6 -> 0.96581206 | Q19: =Q$5*Q11^Q$6 -> 0.94966649 | R19: =R$5*R11^R$6 -> 0.91519281 | S19: =S$5*S11^S$6 -> 0.88882486 | T19: =T$5*T11^T$6 -> 0.87011965 | U19: =U$5*U11^U$6 -> 0.84885577 | V19: =V$5*V11^V$6 -> 0.82183892 | ... OW19: =OW$5*OW11^OW$6 -> 0.31
A20: SC_SLCP_2024-11-28.xlsx | B20: Physical | L20: decay-Nox | M20: 1 | N20: 0.9 | O20: =O$3*O12^O$4 -> 0.80018025 | P20: =P$3*P12^P$4 -> 0.73974608 | Q20: =Q$3*Q12^Q$4 -> 0.69355241 | R20: =R$3*R12^R$4 -> 0.65176343 | S20: =S$3*S12^S$4 -> 0.62530331 | T20: =T$3*T12^T$4 -> 0.6034367 | U20: =U$3*U12^U$4 -> 0.58577724 | V20: =V$3*V12^V$4 -> 0.57556985 | ... OW20: =OW$3*OW12^OW$4 -> 0.31
A21: SC_SLCP_2024-11-28.xlsx | B21: Physical | L21: decay-SO2 | M21: 1 | N21: 0.9 | O21: =O$3*O13^O$4 -> 0.82499317 | P21: =P$3*P13^P$4 -> 0.76839447 | Q21: =Q$3*Q13^Q$4 -> 0.7232491 | R21: =R$3*R13^R$4 -> 0.68166023 | S21: =S$3*S13^S$4 -> 0.65444791 | T21: =T$3*T13^T$4 -> 0.63098952 | U21: =U$3*U13^U$4 -> 0.61283248 | V21: =V$3*V13^V$4 -> 0.60075943 | ... OW21: =OW$3*OW13^OW$4 -> 0.31
A22: SC_SLCP_2024-11-28.xlsx | B22: Physical | L22: decay-NH3 | M22: 1 | N22: 0.9 | O22: =O$3*O14^O$4 -> 0.80018025 | P22: =P$3*P14^P$4 -> 0.73974608 | Q22: =Q$3*Q14^Q$4 -> 0.69355241 | R22: =R$3*R14^R$4 -> 0.65176343 | S22: =S$3*S14^S$4 -> 0.62530331 | T22: =T$3*T14^T$4 -> 0.6034367 | U22: =U$3*U14^U$4 -> 0.58577724 | V22: =V$3*V14^V$4 -> 0.57556985 | ... OW22: =OW$3*OW14^OW$4 -> 0.31
A23: SC_SLCP_2024-11-28.xlsx | B23: Physical | L23: temp-share Pmres | M23: 0 | N23: =(M15-N15)/($M15-$OW15) -> 0.14492754 | O23: =(N15-O15)/($M15-$OW15) -> 0.10870555 | P23: =(O15-P15)/($M15-$OW15) -> 0.082027101 | Q23: =(P15-Q15)/($M15-$OW15) -> 0.065428071 | R23: =(Q15-R15)/($M15-$OW15) -> 0.060273732 | S23: =(R15-S15)/($M15-$OW15) -> 0.039438134 | T23: =(S15-T15)/($M15-$OW15) -> 0.033997673 | U23: =(T15-U15)/($M15-$OW15) -> 0.026314547 | ... OW23: =(OV15-OW15)/($M15-$OW15) -> 0.00073180723
A24: SC_SLCP_2024-11-28.xlsx | B24: Physical | L24: temp-share BC | M24: 0 | N24: =(M16-N16)/($M16-$OW16) -> 0.14492754 | O24: =(N16-O16)/($M16-$OW16) -> 0.10870555 | P24: =(O16-P16)/($M16-$OW16) -> 0.082027101 | Q24: =(P16-Q16)/($M16-$OW16) -> 0.065428071 | R24: =(Q16-R16)/($M16-$OW16) -> 0.060273732 | S24: =(R16-S16)/($M16-$OW16) -> 0.039438134 | T24: =(S16-T16)/($M16-$OW16) -> 0.033997673 | U24: =(T16-U16)/($M16-$OW16) -> 0.026314547 | ... OW24: =(OV16-OW16)/($M16-$OW16) -> 0.00073180723
A25: SC_SLCP_2024-11-28.xlsx | B25: Physical | L25: temp-share OC | M25: 0 | N25: =(M17-N17)/($M17-$OW17) -> 0.14492754 | O25: =(N17-O17)/($M17-$OW17) -> 0.10870555 | P25: =(O17-P17)/($M17-$OW17) -> 0.082027101 | Q25: =(P17-Q17)/($M17-$OW17) -> 0.065428071 | R25: =(Q17-R17)/($M17-$OW17) -> 0.060273732 | S25: =(R17-S17)/($M17-$OW17) -> 0.039438134 | T25: =(S17-T17)/($M17-$OW17) -> 0.033997673 | U25: =(T17-U17)/($M17-$OW17) -> 0.026314547 | ... OW25: =(OV17-OW17)/($M17-$OW17) -> 0.00073180723
A26: SC_SLCP_2024-11-28.xlsx | B26: Physical | L26: temp-share NMVOC | M26: 0 | N26: =(M18-N18)/($M18-$OW18) -> 0.14492754 | O26: =(N18-O18)/($M18-$OW18) -> 0.14466631 | P26: =(O18-P18)/($M18-$OW18) -> 0.087585753 | Q26: =(P18-Q18)/($M18-$OW18) -> 0.066947345 | R26: =(Q18-R18)/($M18-$OW18) -> 0.060563745 | S26: =(R18-S18)/($M18-$OW18) -> 0.038348001 | T26: =(S18-T18)/($M18-$OW18) -> 0.031690734 | U26: =(T18-U18)/($M18-$OW18) -> 0.025593415 | ... OW26: =(OV18-OW18)/($M18-$OW18) -> 0.00072772536
A27: SC_SLCP_2024-11-28.xlsx | B27: Physical | L27: temp-share CH4 | M27: 0 | N27: =(M19-N19)/($M19-$OW19) -> 0.014492754 | O27: =(N19-O19)/($M19-$OW19) -> 0.0057240406 | P27: =(O19-P19)/($M19-$OW19) -> 0.029330946 | Q27: =(P19-Q19)/($M19-$OW19) -> 0.023399377 | R27: =(Q19-R19)/($M19-$OW19) -> 0.049961847 | S27: =(R19-S19)/($M19-$OW19) -> 0.03821442 | T27: =(S19-T19)/($M19-$OW19) -> 0.027109009 | U27: =(T19-U19)/($M19-$OW19) -> 0.030817212 | ... OW27: =(OV19-OW19)/($M19-$OW19) -> 0.00075637321
A28: SC_SLCP_2024-11-28.xlsx | B28: Physical | L28: temp-share Nox | M28: 0 | N28: =(M20-N20)/($M20-$OW20) -> 0.14492754 | O28: =(N20-O20)/($M20-$OW20) -> 0.14466631 | P28: =(O20-P20)/($M20-$OW20) -> 0.087585753 | Q28: =(P20-Q20)/($M20-$OW20) -> 0.066947345 | R28: =(Q20-R20)/($M20-$OW20) -> 0.060563745 | S28: =(R20-S20)/($M20-$OW20) -> 0.038348001 | T28: =(S20-T20)/($M20-$OW20) -> 0.031690734 | U28: =(T20-U20)/($M20-$OW20) -> 0.025593415 | ... OW28: =(OV20-OW20)/($M20-$OW20) -> 0.00072772536
A29: SC_SLCP_2024-11-28.xlsx | B29: Physical | L29: temp-share SO2 | M29: 0 | N29: =(M21-N21)/($M21-$OW21) -> 0.14492754 | O29: =(N21-O21)/($M21-$OW21) -> 0.10870555 | P29: =(O21-P21)/($M21-$OW21) -> 0.082027101 | Q29: =(P21-Q21)/($M21-$OW21) -> 0.065428071 | R29: =(Q21-R21)/($M21-$OW21) -> 0.060273732 | S29: =(R21-S21)/($M21-$OW21) -> 0.039438134 | T29: =(S21-T21)/($M21-$OW21) -> 0.033997673 | U29: =(T21-U21)/($M21-$OW21) -> 0.026314547 | ... OW29: =(OV21-OW21)/($M21-$OW21) -> 0.00073180723
A30: SC_SLCP_2024-11-28.xlsx | B30: Physical | L30: temp-share NH3 | M30: 0 | N30: =(M22-N22)/($M22-$OW22) -> 0.14492754 | O30: =(N22-O22)/($M22-$OW22) -> 0.14466631 | P30: =(O22-P22)/($M22-$OW22) -> 0.087585753 | Q30: =(P22-Q22)/($M22-$OW22) -> 0.066947345 | R30: =(Q22-R22)/($M22-$OW22) -> 0.060563745 | S30: =(R22-S22)/($M22-$OW22) -> 0.038348001 | T30: =(S22-T22)/($M22-$OW22) -> 0.031690734 | U30: =(T22-U22)/($M22-$OW22) -> 0.025593415 | ... OW30: =(OV22-OW22)/($M22-$OW22) -> 0.00072772536
A31: SC_SLCP_2024-11-28.xlsx | B31: Economic | C31: SCPMres | D31: 0.025 | E31: Mid | F31: 2020 | G31: PMres | J31: =NPV(D31,N31:OW31) -> 1399.7501 | K31: =$K$178 -> 2225.6708 | M31: =$K31*M$23 -> 0 | N31: =$K31*N$23 -> 322.56099 | O31: =$K31*O$23 -> 241.94277 | P31: =$K31*P$23 -> 182.56533 | Q31: =$K31*Q$23 -> 145.62135 | R31: =$K31*R$23 -> 134.14949 | S31: =$K31*S$23 -> 87.776305 | T31: =$K31*T$23 -> 75.667629 | ... OW31: =$K31*OW$23 -> 1.628762
A32: SC_SLCP_2024-11-28.xlsx | B32: Economic | C32: SCPMres | D32: 0.02 | E32: Mid | F32: 2020 | G32: PMres | J32: =NPV(D32,N32:OW32) -> 1658.236 | K32: =$K$179 -> 2539.4101 | M32: =$K32*M$23 -> 0 | N32: =$K32*N$23 -> 368.03044 | O32: =$K32*O$23 -> 276.04797 | P32: =$K32*P$23 -> 208.30045 | Q32: =$K32*Q$23 -> 166.1487 | R32: =$K32*R$23 -> 153.05972 | S32: =$K32*S$23 -> 100.14959 | T32: =$K32*T$23 -> 86.334033 | ... OW32: =$K32*OW$23 -> 1.8583586
A33: SC_SLCP_2024-11-28.xlsx | B33: Economic | C33: SCPMres | D33: 0.015 | E33: Mid | F33: 2020 | G33: PMres | J33: =NPV(D33,N33:OW33) -> 2290.7864 | K33: =$K$180 -> 3350.687 | M33: =$K33*M$23 -> 0 | N33: =$K33*N$23 -> 485.60681 | O33: =$K33*O$23 -> 364.23827 | P33: =$K33*P$23 -> 274.84714 | Q33: =$K33*Q$23 -> 219.22899 | R33: =$K33*R$23 -> 201.95841 | S33: =$K33*S$23 -> 132.14484 | T33: =$K33*T$23 -> 113.91556 | ... OW33: =$K33*OW$23 -> 2.452057
A34: SC_SLCP_2024-11-28.xlsx | B34: Economic | C34: SCPMres | D34: 0.025 | E34: Mid | F34: 2025 | G34: PMres | J34: =NPV(D34,N34:OW34) -> 1722.7693 | K34: =AVERAGE(K31,K37) -> 2739.2872 | M34: =$K34*M$23 -> 0 | N34: =$K34*N$23 -> 396.99814 | O34: =$K34*O$23 -> 297.77572 | P34: =$K34*P$23 -> 224.69579 | Q34: =$K34*Q$23 -> 179.22628 | R34: =$K34*R$23 -> 165.10706 | S34: =$K34*S$23 -> 108.03238 | T34: =$K34*T$23 -> 93.12939 | ... OW34: =$K34*OW$23 -> 2.0046302
A35: SC_SLCP_2024-11-28.xlsx | B35: Economic | C35: SCPMres | D35: 0.02 | E35: Mid | F35: 2025 | G35: PMres | J35: =NPV(D35,N35:OW35) -> 2072.795 | K35: =AVERAGE(K32,K38) -> 3174.2626 | M35: =$K35*M$23 -> 0 | N35: =$K35*N$23 -> 460.03806 | O35: =$K35*O$23 -> 345.05996 | P35: =$K35*P$23 -> 260.37556 | Q35: =$K35*Q$23 -> 207.68588 | R35: =$K35*R$23 -> 191.32465 | S35: =$K35*S$23 -> 125.18699 | T35: =$K35*T$23 -> 107.91754 | ... OW35: =$K35*OW$23 -> 2.3229483
A36: SC_SLCP_2024-11-28.xlsx | B36: Economic | C36: SCPMres | D36: 0.015 | E36: Mid | F36: 2025 | G36: PMres | J36: =NPV(D36,N36:OW36) -> 2738.9838 | K36: =AVERAGE(K33,K39) -> 4006.2562 | M36: =$K36*M$23 -> 0 | N36: =$K36*N$23 -> 580.61684 | O36: =$K36*O$23 -> 435.50228 | P36: =$K36*P$23 -> 328.62158 | Q36: =$K36*Q$23 -> 262.12161 | R36: =$K36*R$23 -> 241.47201 | S36: =$K36*S$23 -> 157.99927 | T36: =$K36*T$23 -> 136.20339 | ... OW36: =$K36*OW$23 -> 2.9318072
A37: SC_SLCP_2024-11-28.xlsx | B37: Economic | C37: SCPMres | D37: 0.025 | E37: Mid | F37: 2030 | G37: PMres | J37: =NPV(D37,N37:OW37) -> 2045.7886 | K37: =$K$181 -> 3252.9035 | M37: =$K37*M$23 -> 0 | N37: =$K37*N$23 -> 471.43529 | O37: =$K37*O$23 -> 353.60866 | P37: =$K37*P$23 -> 266.82625 | Q37: =$K37*Q$23 -> 212.8312 | R37: =$K37*R$23 -> 196.06464 | S37: =$K37*S$23 -> 128.28845 | T37: =$K37*T$23 -> 110.59115 | ... OW37: =$K37*OW$23 -> 2.3804983
A38: SC_SLCP_2024-11-28.xlsx | B38: Economic | C38: SCPMres | D38: 0.02 | E38: Mid | F38: 2030 | G38: PMres | J38: =NPV(D38,N38:OW38) -> 2487.354 | K38: =$K$182 -> 3809.1151 | M38: =$K38*M$23 -> 0 | N38: =$K38*N$23 -> 552.04567 | O38: =$K38*O$23 -> 414.07195 | P38: =$K38*P$23 -> 312.45067 | Q38: =$K38*Q$23 -> 249.22305 | R38: =$K38*R$23 -> 229.58958 | S38: =$K38*S$23 -> 150.22439 | T38: =$K38*T$23 -> 129.50105 | ... OW38: =$K38*OW$23 -> 2.787538
A39: SC_SLCP_2024-11-28.xlsx | B39: Economic | C39: SCPMres | D39: 0.015 | E39: Mid | F39: 2030 | G39: PMres | J39: =NPV(D39,N39:OW39) -> 3187.1811 | K39: =$K$183 -> 4661.8254 | M39: =$K39*M$23 -> 0 | N39: =$K39*N$23 -> 675.62686 | O39: =$K39*O$23 -> 506.76629 | P39: =$K39*P$23 -> 382.39602 | Q39: =$K39*Q$23 -> 305.01424 | R39: =$K39*R$23 -> 280.98561 | S39: =$K39*S$23 -> 183.85369 | T39: =$K39*T$23 -> 158.49121 | ... OW39: =$K39*OW$23 -> 3.4115575
A40: SC_SLCP_2024-11-28.xlsx | B40: Economic | C40: SCPMres | D40: 0.025 | E40: Mid | F40: 2035 | G40: PMres | J40: =NPV(D40,N40:OW40) -> 2476.4809 | K40: =AVERAGE(K37,K43) -> 3937.7253 | M40: =$K40*M$23 -> 0 | N40: =$K40*N$23 -> 570.68483 | O40: =$K40*O$23 -> 428.05259 | P40: =$K40*P$23 -> 323.00019 | Q40: =$K40*Q$23 -> 257.63777 | R40: =$K40*R$23 -> 237.3414 | S40: =$K40*S$23 -> 155.29654 | T40: =$K40*T$23 -> 133.8735 | ... OW40: =$K40*OW$23 -> 2.8816558
...

Sheet C-source
R5: U.S. Environmental Protection Agency (EPA), 2022. External Review Draft of Report on the Social Cost of Greenhouse Gases: Estimates Incorporating Recent Scientific Advances. Washington, DC: EPA. Available at: [insert the document's URL or access details if online] [Accessed 29 November 2024].
R18: Link to source:
R19: epa_scghg_report_draft_0.pdf

Sheet CF
B2: Conversion Factor (CF)
B4: Euro | C4: USD ($)
B5: 0.876 | C5: 1

Sheet C-cost per pollutant
A1: Discount rate | B1: Comparator | C1: Scenario year | D1: Unit-cost | E1: Unit
A2: 0.015 | B2: SCBC | C2: 2050 | D2: =SUMIFS(temp_decay[Net Present Value (NPV)],temp_decay[Scenario year],C_CPP[[#This Row],[Scenario year]],temp_decay[Discount rate],C_CPP[[#This Row],[Discount rate]],temp_decay[Ref_SC],C_CPP[[#This Row],[Comparator]]) -> 5278.7688 | E2: [Euro per metric ton of pollutant]
A3: 0.015 | B3: SCBC | C3: 2045 | D3: =SUMIFS(temp_decay[Net Present Value (NPV)],temp_decay[Scenario year],C_CPP[[#This Row],[Scenario year]],temp_decay[Discount rate],C_CPP[[#This Row],[Discount rate]],temp_decay[Ref_SC],C_CPP[[#This Row],[Comparator]]) -> 4730.972 | E3: [Euro per metric ton of pollutant]
A4: 0.015 | B4: SCBC | C4: 2040 | D4: =SUMIFS(temp_decay[Net Present Value (NPV)],temp_decay[Scenario year],C_CPP[[#This Row],[Scenario year]],temp_decay[Discount rate],C_CPP[[#This Row],[Discount rate]],temp_decay[Ref_SC],C_CPP[[#This Row],[Comparator]]) -> 4183.1752 | E4: [Euro per metric ton of pollutant]
A5: 0.015 | B5: SCBC | C5: 2035 | D5: =SUMIFS(temp_decay[Net Present Value (NPV)],temp_decay[Scenario year],C_CPP[[#This Row],[Scenario year]],temp_decay[Discount rate],C_CPP[[#This Row],[Discount rate]],temp_decay[Ref_SC],C_CPP[[#This Row],[Comparator]]) -> 3685.1782 | E5: [Euro per metric ton of pollutant]
A6: 0.015 | B6: SCBC | C6: 2030 | D6: =SUMIFS(temp_decay[Net Present Value (NPV)],temp_decay[Scenario year],C_CPP[[#This Row],[Scenario year]],temp_decay[Discount rate],C_CPP[[#This Row],[Discount rate]],temp_decay[Ref_SC],C_CPP[[#This Row],[Comparator]]) -> 3187.1811 | E6: [Euro per metric ton of pollutant]
A7: 0.015 | B7: SCBC | C7: 2025 | D7: =SUMIFS(temp_decay[Net Present Value (NPV)],temp_decay[Scenario year],C_CPP[[#This Row],[Scenario year]],temp_decay[Discount rate],C_CPP[[#This Row],[Discount rate]],temp_decay[Ref_SC],C_CPP[[#This Row],[Comparator]]) -> 2738.9838 | E7: [Euro per metric ton of pollutant]
A8: 0.015 | B8: SCBC | C8: 2020 | D8: =SUMIFS(temp_decay[Net Present Value (NPV)],temp_decay[Scenario year],C_CPP[[#This Row],[Scenario year]],temp_decay[Discount rate],C_CPP[[#This Row],[Discount rate]],temp_decay[Ref_SC],C_CPP[[#This Row],[Comparator]]) -> 2290.7864 | E8: [Euro per metric ton of pollutant]
A9: 0.015 | B9: SCBC | C9: 2015 | D9: 1735.8754 | E9: [Euro per metric ton of pollutant]
A10: 0.015 | B10: SCC | C10: 2050 | D10: =SUMIFS(temp_decay[Net Present Value (NPV)],temp_decay[Scenario year],C_CPP[[#This Row],[Scenario year]],temp_decay[Discount rate],C_CPP[[#This Row],[Discount rate]],temp_decay[Ref_SC],C_CPP[[#This Row],[Comparator]]) -> 420.5 | E10: [Euro per metric ton of pollutant]
A11: 0.015 | B11: SCC | C11: 2045 | D11: =SUMIFS(temp_decay[Net Present Value (NPV)],temp_decay[Scenario year],C_CPP[[#This Row],[Scenario year]],temp_decay[Discount rate],C_CPP[[#This Row],[Discount rate]],temp_decay[Ref_SC],C_CPP[[#This Row],[Comparator]]) -> 398.58 | E11: [Euro per metric ton of pollutant]
A12: 0.015 | B12: SCC | C12: 2040 | D12: =SUMIFS(temp_decay[Net Present Value (NPV)],temp_decay[Scenario year],C_CPP[[#This Row],[Scenario year]],temp_decay[Discount rate],C_CPP[[#This Row],[Discount rate]],temp_decay[Ref_SC],C_CPP[[#This Row],[Comparator]]) -> 376.7 | E12: [Euro per metric ton of pollutant]
A13: 0.015 | B13: SCC | C13: 2035 | D13: =SUMIFS(temp_decay[Net Present Value (NPV)],temp_decay[Scenario year],C_CPP[[#This Row],[Scenario year]],temp_decay[Discount rate],C_CPP[[#This Row],[Discount rate]],temp_decay[Ref_SC],C_CPP[[#This Row],[Comparator]]) -> 354.78 | E13: [Euro per metric ton of pollutant]
A14: 0.015 | B14: SCC | C14: 2030 | D14: =SUMIFS(temp_decay[Net Present Value (NPV)],temp_decay[Scenario year],C_CPP[[#This Row],[Scenario year]],temp_decay[Discount rate],C_CPP[[#This Row],[Discount rate]],temp_decay[Ref_SC],C_CPP[[#This Row],[Comparator]]) -> 332.9 | E14: [Euro per metric ton of pollutant]
A15: 0.015 | B15: SCC | C15: 2025 | D15: =SUMIFS(temp_decay[Net Present Value (NPV)],temp_decay[Scenario year],C_CPP[[#This Row],[Scenario year]],temp_decay[Discount rate],C_CPP[[#This Row],[Discount rate]],temp_decay[Ref_SC],C_CPP[[#This Row],[Comparator]]) -> 315.36 | E15: [Euro per metric ton of pollutant]
A16: 0.015 | B16: SCC | C16: 2020 | D16: =SUMIFS(temp_decay[Net Present Value (NPV)],temp_decay[Scenario year],C_CPP[[#This Row],[Scenario year]],temp_decay[Discount rate],C_CPP[[#This Row],[Discount rate]],temp_decay[Ref_SC],C_CPP[[#This Row],[Comparator]]) -> 297.8 | E16: [Euro per metric ton of pollutant]
A17: 0.015 | B17: SCC | C17: 2015 | D17: 274.04 | E17: [Euro per metric ton of pollutant]
A18: 0.015 | B18: SCM | C18: 2050 | D18: =SUMIFS(temp_decay[Net Present Value (NPV)],temp_decay[Scenario year],C_CPP[[#This Row],[Scenario year]],temp_decay[Discount rate],C_CPP[[#This Row],[Discount rate]],temp_decay[Ref_SC],C_CPP[[#This Row],[Comparator]]) -> 4642.8 | E18: [Euro per metric ton of pollutant]
A19: 0.015 | B19: SCM | C19: 2045 | D19: =SUMIFS(temp_decay[Net Present Value (NPV)],temp_decay[Scenario year],C_CPP[[#This Row],[Scenario year]],temp_decay[Discount rate],C_CPP[[#This Row],[Discount rate]],temp_decay[Ref_SC],C_CPP[[#This Row],[Comparator]]) -> 4161 | E19: [Euro per metric ton of pollutant]
A20: 0.015 | B20: SCM | C20: 2040 | D20: =SUMIFS(temp_decay[Net Present Value (NPV)],temp_decay[Scenario year],C_CPP[[#This Row],[Scenario year]],temp_decay[Discount rate],C_CPP[[#This Row],[Discount rate]],temp_decay[Ref_SC],C_CPP[[#This Row],[Comparator]]) -> 3679.2 | E20: [Euro per metric ton of pollutant]
A21: 0.015 | B21: SCM | C21: 2035 | D21: =SUMIFS(temp_decay[Net Present Value (NPV)],temp_decay[Scenario year],C_CPP[[#This Row],[Scenario year]],temp_decay[Discount rate],C_CPP[[#This Row],[Discount rate]],temp_decay[Ref_SC],C_CPP[[#This Row],[Comparator]]) -> 3241.2 | E21: [Euro per metric ton of pollutant]
A22: 0.015 | B22: SCM | C22: 2030 | D22: =SUMIFS(temp_decay[Net Present Value (NPV)],temp_decay[Scenario year],C_CPP[[#This Row],[Scenario year]],temp_decay[Discount rate],C_CPP[[#This Row],[Discount rate]],temp_decay[Ref_SC],C_CPP[[#This Row],[Comparator]]) -> 2803.2 | E22: [Euro per metric ton of pollutant]
A23: 0.015 | B23: SCM | C23: 2025 | D23: =SUMIFS(temp_decay[Net Present Value (NPV)],temp_decay[Scenario year],C_CPP[[#This Row],[Scenario year]],temp_decay[Discount rate],C_CPP[[#This Row],[Discount rate]],temp_decay[Ref_SC],C_CPP[[#This Row],[Comparator]]) -> 2409 | E23: [Euro per metric ton of pollutant]
A24: 0.015 | B24: SCM | C24: 2020 | D24: =SUMIFS(temp_decay[Net Present Value (NPV)],temp_decay[Scenario year],C_CPP[[#This Row],[Scenario year]],temp_decay[Discount rate],C_CPP[[#This Row],[Discount rate]],temp_decay[Ref_SC],C_CPP[[#This Row],[Comparator]]) -> 2014.8 | E24: [Euro per metric ton of pollutant]
A25: 0.015 | B25: SCM | C25: 2015 | D25: 1526.7429 | E25: [Euro per metric ton of pollutant]
A26: 0.015 | B26: SC-N2O | C26: 2050 | D26: =SUMIFS(temp_decay[Net Present Value (NPV)],temp_decay[Scenario year],C_CPP[[#This Row],[Scenario year]],temp_decay[Discount rate],C_CPP[[#This Row],[Discount rate]],temp_decay[Ref_SC],C_CPP[[#This Row],[Comparator]]) -> 122640 | E26: [Euro per metric ton of pollutant]
A27: 0.015 | B27: SC-N2O | C27: 2045 | D27: =SUMIFS(temp_decay[Net Present Value (NPV)],temp_decay[Scenario year],C_CPP[[#This Row],[Scenario year]],temp_decay[Discount rate],C_CPP[[#This Row],[Discount rate]],temp_decay[Ref_SC],C_CPP[[#This Row],[Comparator]]) -> 113880 | E27: [Euro per metric ton of pollutant]
A28: 0.015 | B28: SC-N2O | C28: 2040 | D28: =SUMIFS(temp_decay[Net Present Value (NPV)],temp_decay[Scenario year],C_CPP[[#This Row],[Scenario year]],temp_decay[Discount rate],C_CPP[[#This Row],[Discount rate]],temp_decay[Ref_SC],C_CPP[[#This Row],[Comparator]]) -> 105120 | E28: [Euro per metric ton of pollutant]
A29: 0.015 | B29: SC-N2O | C29: 2035 | D29: =SUMIFS(temp_decay[Net Present Value (NPV)],temp_decay[Scenario year],C_CPP[[#This Row],[Scenario year]],temp_decay[Discount rate],C_CPP[[#This Row],[Discount rate]],temp_decay[Ref_SC],C_CPP[[#This Row],[Comparator]]) -> 96360 | E29: [Euro per metric ton of pollutant]
A30: 0.015 | B30: SC-N2O | C30: 2030 | D30: =SUMIFS(temp_decay[Net Present Value (NPV)],temp_decay[Scenario year],C_CPP[[#This Row],[Scenario year]],temp_decay[Discount rate],C_CPP[[#This Row],[Discount rate]],temp_decay[Ref_SC],C_CPP[[#This Row],[Comparator]]) -> 87600 | E30: [Euro per metric ton of pollutant]
A31: 0.015 | B31: SC-N2O | C31: 2025 | D31: =SUMIFS(temp_decay[Net Present Value (NPV)],temp_decay[Scenario year],C_CPP[[#This Row],[Scenario year]],temp_decay[Discount rate],C_CPP[[#This Row],[Discount rate]],temp_decay[Ref_SC],C_CPP[[#This Row],[Comparator]]) -> 81906 | E31: [Euro per metric ton of pollutant]
A32: 0.015 | B32: SC-N2O | C32: 2020 | D32: =SUMIFS(temp_decay[Net Present Value (NPV)],temp_decay[Scenario year],C_CPP[[#This Row],[Scenario year]],temp_decay[Discount rate],C_CPP[[#This Row],[Discount rate]],temp_decay[Ref_SC],C_CPP[[#This Row],[Comparator]]) -> 76212 | E32: [Euro per metric ton of pollutant]
A33: 0.015 | B33: SC-N2O | C33: 2015 | D33: 66138 | E33: [Euro per metric ton of pollutant]
A34: 0.015 | B34: SCNH3 | C34: 2050 | D34: =SUMIFS(temp_decay[Net Present Value (NPV)],temp_decay[Scenario year],C_CPP[[#This Row],[Scenario year]],temp_decay[Discount rate],C_CPP[[#This Row],[Discount rate]],temp_decay[Ref_SC],C_CPP[[#This Row],[Comparator]]) -> 5357.5469 | E34: [Euro per metric ton of pollutant]
A35: 0.015 | B35: SCNH3 | C35: 2045 | D35: =SUMIFS(temp_decay[Net Present Value (NPV)],temp_decay[Scenario year],C_CPP[[#This Row],[Scenario year]],temp_decay[Discount rate],C_CPP[[#This Row],[Discount rate]],temp_decay[Ref_SC],C_CPP[[#This Row],[Comparator]]) -> 4801.5751 | E35: [Euro per metric ton of pollutant]
A36: 0.015 | B36: SCNH3 | C36: 2040 | D36: =SUMIFS(temp_decay[Net Present Value (NPV)],temp_decay[Scenario year],C_CPP[[#This Row],[Scenario year]],temp_decay[Discount rate],C_CPP[[#This Row],[Discount rate]],temp_decay[Ref_SC],C_CPP[[#This Row],[Comparator]]) -> 4245.6032 | E36: [Euro per metric ton of pollutant]
A37: 0.015 | B37: SCNH3 | C37: 2035 | D37: =SUMIFS(temp_decay[Net Present Value (NPV)],temp_decay[Scenario year],C_CPP[[#This Row],[Scenario year]],temp_decay[Discount rate],C_CPP[[#This Row],[Discount rate]],temp_decay[Ref_SC],C_CPP[[#This Row],[Comparator]]) -> 3740.1743 | E37: [Euro per metric ton of pollutant]
